Workbook
Name 技术状态分级: #REF!
Name 进度状态分级: #REF!
Name 客户满意度分级: #REF!
Name 数据月: #REF!
Name 项目状态: #REF!
Name 项目状态分级: #REF!
Name 状态: #REF!
Name 状态分级: #REF!
Name 资源状态分级: #REF!
Name 技术状态分级: #REF!
Name 进度状态分级: #REF!
Name 客户满意度分级: #REF!
Name 数据月: #REF!
Name 项目状态: #REF!
Name 项目状态分级: #REF!
Name 状态: #REF!
Name 状态分级: #REF!
Name 资源状态分级: #REF!
Name 技术状态分级: #REF!
Name 进度状态分级: #REF!
Name 客户满意度分级: #REF!
Name 数据月: #REF!
Name 项目状态: #REF!
Name 项目状态分级: #REF!
Name 状态: #REF!
Name 状态分级: #REF!
Name 资源状态分级: #REF!
Name 技术状态分级: #REF!
Name 进度状态分级: #REF!
Name 客户满意度分级: #REF!
Name 数据月: #REF!
Name 项目状态: #REF!
Name 项目状态分级: #REF!
Name 状态: #REF!
Name 状态分级: #REF!
Name 资源状态分级: #REF!
Name 技术状态分级: #REF!
Name 进度状态分级: #REF!
Name 客户满意度分级: #REF!
Name 数据月: #REF!
Name 项目状态: #REF!
Name 项目状态分级: #REF!
Name 状态: #REF!
Name 状态分级: #REF!
Name 资源状态分级: #REF!
Name 技术状态分级: #REF!
Name 进度状态分级: #REF!
Name 客户满意度分级: #REF!
Name 数据月: #REF!
Name 项目状态: #REF!
Name 项目状态分级: #REF!
Name 状态: #REF!
Name 状态分级: #REF!
Name 资源状态分级: #REF!

Sheet 辅助
A1: 损益归类（T列） | B1: 项目维度（U列） | C1: *杜邦损益归类（V列） | D1: 归类 | E1: QA关注（B列可看详细的明细维度）
A2: 自有交付收入 | B2: 收入 | C2: 自有交付收入 | D2: 收入
A3: 客户付费收入 | B3: 收入 | C3: 客户付费收入 | D3: 收入
A4: 加班收入 | B4: 收入 | C4: 加班收入 | D4: 收入
A5: 分包收入 | B5: 收入 | C5: 分包收入 | D5: 收入
A6: 软硬件销售收入 | B6: 收入 | C6: 其他业务收入 | D6: 收入
A7: 税金及附加 | B7: 税金及附加 | C7: 税金及附加 | D7: 税金及附加
A8: 采购税金及附加 | B8: 税金及附加 | C8: 采购税金及附加 | D8: 税金及附加
A9: Billable人工成本 | B9: 人工 | C9: Billable人工成本 | D9: 成本1 | E9: ✔
A10: Billable社保+公积金 | B10: 人工 | C10: Billable人工成本 | D10: 成本1 | E10: ✔
A11: 加班工资 | B11: 人工 | C11: 加班工资 | D11: 成本1 | E11: ✔
A12: Training人工成本 | B12: 人工 | C12: Unbillable人工成本 | D12: 成本2 | E12: ✔
A13: Unbillable人工成本BK | B13: 人工 | C13: Unbillable人工成本 | D13: 成本2 | E13: ✔
A14: Unbillable社保+公积金 | B14: 人工 | C14: Unbillable人工成本 | D14: 成本2 | E14: ✔
A15: Unbillable社保+公积金BK | B15: 人工 | C15: Unbillable人工成本 | D15: 成本2 | E15: ✔
A16: 项目闲置成本 | B16: 人工 | C16: Unbillable人工成本 | D16: 成本2 | E16: ✔
A17: Release人工成本 | B17: 人工 | C17: Unbillable人工成本 | D17: 成本2
A18: 其他Release人工成本 | B18: 人工 | C18: Unbillable人工成本 | D18: 成本2
A19: 三期员工闲置成本 | B19: 人工 | C19: Unbillable人工成本 | D19: 成本2
A20: 项目其他人工成本 | B20: 人工 | C20: 其他人工成本（激励、津贴） | D20: 成本2
A21: 岗位津贴 | B21: 人工 | C21: 其他人工成本（激励、津贴） | D21: 成本2
A22: 晚餐补助 | B22: 人工 | C22: 其他人工成本（激励、津贴） | D22: 成本2
A23: 高绩效奖金 | B23: 人工 | C23: 其他人工成本（激励、津贴） | D23: 成本2
A24: FP独立核算奖金 | B24: 人工 | C24: 其他人工成本（激励、津贴） | D24: 成本2
A25: 项目其他激励成本 | B25: 人工 | C25: 其他人工成本（激励、津贴） | D25: 成本2
A26: 项目交付分包 | B26: 交付分包成本 | C26: 分包成本 | D26: 成本3
A27: 销售分包成本 | B27: 交付分包成本 | C27: 分包成本 | D27: 成本3
A28: 云资源成本 | D28: 成本3
A29: 项目差旅费用（非客户付费） | B29: 费用 | C29: 差旅费 | D29: 成本3 | E29: ✔
A30: 项目客户付费成本 | B30: 费用 | C30: 客户付费（差旅、场地等） | D30: 成本3
A31: 项目其他报销费用 | B31: 费用 | C31: 交付部其他成本 | D31: 成本3 | E31: ✔设备、云资源、OEP日常报销、体检、商报等
A32: 交付部管理房租/物业/水电 | B32: 费用 | C32: 交付部房租物业水电 | D32: 成本4
A33: 交付部资产折旧/装修摊销 | B33: 费用 | C33: 交付部折旧摊销 | D33: 成本4
A34: 交付部管理人工 | B34: 人工 | C34: 其中：管理人工成本（含五险一金） | D34: 成本4
A35: 交付部管理费用 | B35: 费用 | C35: 其中：管理其他费用 | D35: 成本4
A36: BU管理人工成本（含五险一金） | B36: 人工 | C36: 其中：管理人工成本（含五险一金） | D36: BU成本
A37: BU管理差旅费用 | B37: 费用 | C37: 其中：管理差旅费用 | D37: BU成本
A38: BU管理其他报销费用 | B38: 费用 | C38: 其中：管理其他费用 | D38: BU成本
A39: BU管理房租/物业/水电 | B39: 费用 | C39: 管理房租物业水电 | D39: BU成本
A40: BU管理资产折旧/装修摊销 | B40: 费用 | C40: 管理折旧摊销 | D40: BU成本
...

Sheet 项目清单
A1: 事业部 | B1: 交付部 | C1: 项目编号 | D1: 项目名称 | E1: 项目开始时间 | F1: 项目结束时间 | G1: 负责QA | H1: 预算成本毛利表是否提交 | I1: 项目阶段 | J1: 是否重点项目 | K1: 备注
A2: 泛AIoT与设备商事业部 | B2: 汽车与泛AIoT交付部 | C2: HWCQP0FF2311F14X11 | D2: 长安汽车泰国销售公司销售售后备件业务系统项目系统开发2 | E2: 45239 | F2: 45443 | G2: 赵云平 | H2: 否 | I2: 已结项 | K2: 已结项
A3: 定制开发事业部 | B3: 运营商软件交付部 | C3: P202112000071 | D3: 2022年上研院工业互联网运维项目 | E3: 44562 | F3: 45838 | G3: 李陶 | H3: 否 | I3: 运维期 | K3: 开发结束，运维期
A4: 定制开发事业部 | B4: 运营商软件交付部 | C4: P202203000237 | D4: 2022年中国铁塔人力运营辅助系统项目 | E4: 44621 | F4: 45382 | G4: 李陶 | H4: 否 | I4: 已结项 | K4: 已结项
A5: 定制开发事业部 | B5: 运营商软件交付部 | C5: P202203000241 | D5: 2022年中国铁塔PMS项目 | E5: 44621 | F5: 45382 | G5: 李陶 | H5: 否 | I5: 已结项 | K5: 已结项
A6: 定制开发事业部 | B6: 解决方案业务部 | C6: P202208000397 | D6: 甘肃省试点地市数据治理项目 | E6: 44788 | F6: 45535 | G6: 崔哲 | H6: 否 | I6: 已结项 | K6: 从CSD转过来的，二期立项金额是276W，后来客户只认177W，因费用削减太多一直没谈妥，暂停支撑 | M6: 预算G列拷贝到实际G列
A7: 移动研究院事业部 | B7: 中移集成交付部 | C7: P202209000298 | D7: 延长物业管理-2024管理系统软件项目合同-FP项目 | E7: 44803 | F7: 45657 | G7: 崔哲 | H7: 否 | I7: 已结项 | K7: 已结项 | M7: 预算I列拷贝到实际N列
A8: 定制开发事业部 | B8: 解决方案业务部 | C8: P202209000457 | D8: 山东中白产业园智慧园区项目 | E8: 44805 | F8: 45382 | G8: 崔哲 | H8: 否 | I8: 已结项 | K8: 已结项 | M8: 实际J列拷贝到预算L列
A9: 定制开发事业部 | B9: 运营商软件交付部 | C9: P202210000190 | D9: 中移动信息2022-2024年智慧中台运营中心一级充值支付中心系统（中软国际）技术开发框架合同-中软 | E9: 44835 | F9: 45657 | G9: 刘科源 | H9: 是 | I9: 进行中 | M9: 预算H列拷贝到实际H列
A10: 定制开发事业部 | B10: 运营商软件交付部 | C10: P202210000301 | D10: 中移动信息2022-2024年智慧中台运营中心一级充值支付中心系统维护服务(中软国际)框架采购 | E10: 44835 | F10: 45657 | G10: 刘科源 | H10: 是 | I10: 进行中
A11: 定制开发事业部 | B11: 运营商软件交付部 | C11: P202211000809 | D11: 湖南人社厅监管监督平台 | E11: 44896 | F11: 46356 | G11: 刘科源 | H11: 否 | I11: 已结项 | K11: 因客户原因，项目实际未实施
A12: 电信与AIoT事业部（虚拟） | B12: 解决方案业务部 | C12: P202212000029 | D12: 农业农村部兽药评审系统项目大厅对接 | E12: 44894 | F12: 45292 | G12: 崔哲 | H12: 否 | I12: 已结项 | K12: 已结项
A13: 定制开发事业部 | B13: 解决方案业务部 | C13: P202212000030 | D13: 2022年安徽省农业科学院畜牧兽医研究所种猪遗传评估系统软件及育种分析服务 | E13: 44903 | F13: 46034 | G13: 崔哲 | H13: 是 | I13: 运维期 | K13: 开发结束，运维期不会有专人投入，有问题就解决问题，毛利不会发生太大变化
A14: 定制开发事业部 | B14: 解决方案业务部 | C14: P202212000032 | D14: 2022年黑龙江省种猪遗传评估信息平台建设项目软件开发项目 | E14: 44900 | F14: 45473 | G14: 崔哲 | H14: 是 | I14: 运维期 | K14: 开发结束，运维期不会有专人投入，有问题就解决问题，毛利不会发生太大变化
A15: 定制开发事业部 | B15: 解决方案业务部 | C15: P202212000496 | D15: 东部地区畜禽遗传资源基因库建设项目仪器设备采购-软件 | E15: 44917 | F15: 46326 | G15: 崔哲 | H15: 是 | I15: 运维期 | K15: 开发结束，运维期不会有专人投入，有问题就解决问题，毛利不会发生太大变化
A16: 泛AIoT与设备商事业部 | B16: 移动通讯交付部 | C16: P202301000370 | D16: 烽火自动化脚本开发及手工测试项目-武汉 | E16: 44915 | F16: 45322 | G16: 崔哲 | H16: 否 | I16: 已结项 | K16: 已结项
A17: 定制开发事业部 | B17: 解决方案业务部 | C17: P202302000041 | D17: OneNet框架项目-整包类-江阴一期项目 | E17: 44964 | F17: 46241 | G17: 崔哲 | H17: 否 | I17: 待验收 | K17: 已交付，待验收
A18: 定制开发事业部 | B18: 解决方案业务部 | C18: P202302000395 | D18: OneNet杭州滨江物联网平台项目 | E18: 44986 | F18: 45412 | G18: 崔哲 | H18: 否 | I18: 待验收 | K18: 已交付，待验收
A19: 定制开发事业部 | B19: 解决方案业务部 | C19: P202303000017 | D19: 兵装集成项目支撑 | E19: 44986 | F19: 45351 | G19: 崔哲 | H19: 否 | I19: 待验收 | K19: 已交付，待验收
A20: 定制开发事业部 | B20: 解决方案业务部 | C20: P202303000518 | D20: OneNET物联网平台数字保定一期建设项目 | E20: 45017 | F20: 45473 | G20: 崔哲 | H20: 否 | I20: 待验收 | K20: 已交付，待验收
A21: 定制开发事业部 | B21: 运营商软件交付部 | C21: P202304000190 | D21: 2023年中国铁塔PMS系统项目 | E21: 45012 | F21: 45743 | G21: 李陶 | H21: 是 | I21: 进行中
A22: 定制开发事业部 | B22: 运营商软件交付部 | C22: P202304000404 | D22: 2023年中国铁塔人力运营辅助系统项目 | E22: 45017 | F22: 45743 | G22: 李陶 | H22: 是 | I22: 进行中
A23: 定制开发事业部 | B23: 运营商软件交付部 | C23: P202304000407 | D23: 2023年中国铁塔AIOT平台项目 | E23: 45017 | F23: 45743 | G23: 李陶 | H23: 是 | I23: 进行中
A24: 定制开发事业部 | B24: 运营商软件交付部 | C24: P202304000410 | D24: 2023年中国铁塔国资监管项目 | E24: 45017 | F24: 45743 | G24: 李陶 | H24: 是 | I24: 进行中
A25: 定制开发事业部 | B25: 运营商软件交付部 | C25: P202304000412 | D25: 2023年中国铁塔大监督项目 | E25: 45017 | F25: 45743 | G25: 李陶 | H25: 是 | I25: 进行中
A26: 定制开发事业部 | B26: 运营商软件交付部 | C26: P202304000415 | D26: 2023年中国铁塔FSU监控项目 | E26: 45017 | F26: 45743 | G26: 李陶 | H26: 是 | I26: 进行中
A27: 定制开发事业部 | B27: 运营商软件交付部 | C27: P202304000416 | D27: 2023年中国铁塔IT服务工单 | E27: 45017 | F27: 45743 | G27: 李陶 | H27: 是 | I27: 进行中
A28: 定制开发事业部 | B28: 运营商软件交付部 | C28: P202304000419 | D28: 2023年中国铁塔能源充电项目 | E28: 45017 | F28: 45743 | G28: 李陶 | H28: 是 | I28: 进行中
A29: 定制开发事业部 | B29: 运营商软件交付部 | C29: P202304000421 | D29: 2023年中国铁塔运维监控项目 | E29: 45017 | F29: 45743 | G29: 李陶 | H29: 是 | I29: 进行中
A30: 移动研究院事业部 | B30: 中移科研交付部 | C30: P202304000706 | D30: 苏研合营云代维项目八期 | E30: 45017 | F30: 45412 | G30: 赵云平 | H30: 否 | I30: 已结项
A31: 定制开发事业部 | B31: 解决方案业务部 | C31: P202304000966 | D31: OneNET江苏南通如东物联网平台运营项目（2年） | E31: 45039 | F31: 45769 | G31: 崔哲 | H31: 否 | I31: 待验收 | K31: 已交付，待验收
A32: 移动研究院事业部 | B32: 中移科研交付部 | C32: P202304001076 | D32: 苏研合营云运维八期_NOPO | E32: 45017 | F32: 45382 | G32: 赵云平 | H32: 否 | I32: 已结项 | K32: 已结项，后续切换成TM模式结算
A33: 定制开发事业部 | B33: 解决方案业务部 | C33: P202305000071 | D33: OneNET宁波驻场运营项目 | E33: 45051 | F33: 45416 | G33: 崔哲 | H33: 否 | I33: 已结项 | K33: 已结项
A34: 定制开发事业部 | B34: 解决方案业务部 | C34: P202305000368 | D34: 扬州经济技术开发区智慧园区管理项目 | E34: 45108 | F34: 46022 | G34: 崔哲 | H34: 否 | I34: 待验收 | K34: 已交付，待验收
A35: 定制开发事业部 | B35: 解决方案业务部 | C35: P202305000493 | D35: OneNET框架龙华物联网定制开发项目 | E35: 45078 | F35: 45443 | G35: 崔哲 | H35: 否 | I35: 待验收 | K35: 已交付，待验收
A36: 定制开发事业部 | B36: 解决方案业务部 | C36: P202305000525 | D36: 中移枣庄分公司-薛城区城市大脑2023-2024-技术开发FP项目 | E36: 45108 | F36: 45473 | G36: 崔哲 | H36: 否 | I36: 待验收 | K36: 已交付，待验收
A37: 泛AIoT与设备商事业部 | B37: 专网交付部 | C37: P202305000596 | D37: 史密斯2023框架合同 | E37: 45047 | F37: 45657 | G37: 赵云平 | H37: 是 | I37: 进行中
A38: 定制开发事业部 | B38: 解决方案业务部 | C38: P202305000630 | D38: 农业农村部兽药评审系统2023年度运维 | E38: 45078 | F38: 45351 | G38: 崔哲 | H38: 否 | I38: 已结项 | K38: 已结项
A39: 定制开发事业部 | B39: 运营商软件交付部 | C39: P202306000020 | D39: 翼支付TOB电商研发项目2023 | E39: 45078 | F39: 45412 | G39: 李陶 | H39: 否 | I39: 已结项 | K39: 已结项
A40: 定制开发事业部 | B40: 解决方案业务部 | C40: P202306000119 | D40: 农业农村部2023年中国乡村资讯等运维和信息服务项目 | E40: 45231 | F40: 45382 | G40: 崔哲 | H40: 是 | I40: 进行中
...

Sheet 在行项目毛利率达标偏差分析
B1: 每月15号左右，数据刷新后，毛利不达标项目发到质量干部工作群 | BF1: 在行FP毛利达标率 | BG1: =14/29 -> 0.48275862 | BH1: =1-BG1 -> 0.51724138
A2: 在行FP项目毛利率达标分析
A3: 事业部 | B3: 项目开始时间 | C3: 项目结束时间 | D3: 项目编码 | E3: 项目名称 | F3: 报价毛利率 | G3: 项目立项毛利率 | H3: 当月毛利率-GP1% | T3: YTD毛利率-GP1% | AF3: 当月毛利率-GP3% | AR3: YTD毛利率-GP3% | BD3: 差距-GP1% | BE3: 差距-GP3% | BF3: 毛利达标-GP1% | BG3: 风险 | BH3: 不达标原因，看GP1%和GP3% | BI3: 措施 | BJ3: 202601月进展 | BK3: 202602月进展 | BL3: 202603月进展 | BM3: 202604月进展 | BN3: 202605月进展 | BO3: 202606月进展 | BP3: 202607月进展 | BQ3: 202608月进展 | BR3: 202609月进展 | BS3: 202610月进展 | BT3: 202611月进展 | BU3: 202612月进展 | BV3: 系统立项GP1
H5: 1月 | I5: 2月 | J5: 3月 | K5: 4月 | L5: 5月 | M5: 6月 | N5: 7月 | O5: 8月 | P5: 9月 | Q5: 10月 | R5: 11月 | S5: 12月 | T5: 1月 | U5: 2月 | V5: 3月 | W5: 4月 | X5: 5月 | Y5: 6月 | Z5: 7月 | AA5: 8月 | AB5: 9月 | AC5: 10月 | AD5: 11月 | AE5: 12月 | AF5: 1月 | AG5: 2月 | AH5: 3月 | AI5: 4月 | AJ5: 5月 | AK5: 6月 | AL5: 7月 | AM5: 8月 | AN5: 9月 | AO5: 10月 | AP5: 11月 | AQ5: 12月 | AR5: 1月 | AS5: 2月 | AT5: 3月 | AU5: 4月 | AV5: 5月 | AW5: 6月 | AX5: 7月 | AY5: 8月 | AZ5: 9月 | BA5: 10月 | BB5: 11月 | BC5: 12月
A6: 电信联通综合事业部 | B6: 45658 | C6: 46387 | D6: / | E6: 农业项目群（当前10个在行项目） | F6: 0.207 | G6: 0.1889 | BD6: =U6-F6 -> -0.207 | BE6: =AS6-G6 -> -0.1889 | BF6: =_xlfn.IFS(BD6<-3%,"不达标",BD6<0%,"基本达标",TRUE,"达标") -> 不达标 | BG6: 低 | BH6: 畜牧核心数据查询APP开发项目和科研项目人力成本超出项目收入 前半年项目断档导致收入无法覆盖团队人力成本导致 | BJ6: 1、全国畜牧总站-畜牧核心数据查询APP开发-FP项目，已于12月中旬上线了并验收回款，后面不再投入。已投入成本超出预算2W，预计全周期GP3%毛利率7.55%，低于预算目标； 2、全国畜牧总站-2025年农生物育种大数据与知识产权支撑体系建设联合实施4-FP项目，12月成本13.76万，超出当月NR 2.9万，导致亏损； | BV6: 0.207
A7: =VLOOKUP(D7,Sheet10!A:B,2,0) -> 电信联通综合事业部 | B7: 45292 | C7: 2026/12/31 | D7: P202312000724 | E7: 南京联创-2024-2025年ICT外部行业专家库服务支撑合同-FP项目 | F7: 0.1944 | G7: 0.1022 | H7: -0.1648 | T7: 0.1181 | AF7: -0.1951 | AR7: 0.0801 | BD7: =U7-F7 -> -0.1944 | BE7: =AS7-G7 -> -0.1022 | BF7: =_xlfn.IFS(BD7<-3%,"不达标",BD7<0%,"基本达标",TRUE,"达标") -> 不达标 | BG7: 低 | BH7: 项目24年nopo立项金额250万，合同前后金额100万，25年1月开始投入交付，项目经理未填报进度导致未计入收入，已要求项目经理在下月补报进度 | BI7: 项目经理根据合同金额调整和变更成本计划，5月开始补报交付进度 | BV7: -0.6469
A8: 电信联通综合事业部 | B8: 45473 | C8: 46142 | D8: P202312000792 | E8: 江苏移动-2025-2027年ICT业务外部行业专家库服务项目支撑服务-FP项目 | F8: 0.1944 | G8: 0.1547 | H8: 0.1134 | T8: 0.6011 | AF8: 0.1033 | AR8: 0.4981 | BD8: =U8-F8 -> -0.1944 | BE8: =AS8-G8 -> -0.1547 | BF8: =_xlfn.IFS(BD8<-3%,"不达标",BD8<0%,"基本达标",TRUE,"达标") -> 不达标 | BG8: 低
A9: =VLOOKUP(D9,Sheet10!A:B,2,0) -> 电信联通综合事业部 | B9: 45447 | C9: 46203 | D9: P202408001258 | E9: 用友-2024年邮政采购三期信科平台新增需求开发外包项目-FP项目 | F9: 0.106 | G9: 0.1002 | H9: 0 | T9: 0.0503 | AF9: 0 | AR9: 0.0396 | BD9: =U9-F9 -> -0.106 | BE9: =AS9-G9 -> -0.1002 | BF9: =_xlfn.IFS(BD9<-3%,"不达标",BD9<0%,"基本达标",TRUE,"达标") -> 不达标 | BG9: 低 | BH9: 该项目为与用友首次合作项目，属于低毛利中标项目，启动后出现需求范围蔓延，研发投入成本较预算增加，预计结项毛利4.97%略低于目标毛利，实际比预算少收入2万左右 | BI9: 2月后仅投入维护人力，采用人力复用方式，不再产生成本 | BV9: 0.1016
A10: =VLOOKUP(D10,Sheet10!A:B,2,0) -> 泛AIoT与设备商事业部 | B10: 45484 | C10: 46052 | D10: P202408000125 | E10: 华勤-2024-2026年WD7205软件测试-鸿蒙化FP项目 | F10: 0.1508 | G10: 0.1257 | H10: 产出为0 成本7188.34 | T10: -0.069667798 | AF10: 产出为0 成本7188.34 | AR10: -0.1018 | BD10: =U10-F10 -> -0.1508 | BE10: =AS10-G10 -> -0.1257 | BF10: =_xlfn.IFS(BD10<-3%,"不达标",BD10<0%,"基本达标",TRUE,"达标") -> 不达标 | BG10: 高 | BH10: 1、当前项目在原定合同上进行增补，目前协议还未签回，只有客户正式邮件，历史产出本月财务进度扎差，预估扎差80W。 2、10月产出未填报到系统中。 还原GP：10月GP1% 10%，GP3% 10%，25年YTD10月GP1 3.98% | BI10: 1、跟踪需求增加及合同签定进展 2、10月实际的产出38W，成本34.2W，再合同签回后实际产出才能体现到系统中， | BK10: 2月已经客户再次沟通确认，客户在走盖章中 | BV10: 0.1214
A11: =VLOOKUP(D11,Sheet10!A:B,2,0) -> 移动省专事业部 | B11: 45597 | C11: 46387 | D11: P202410000919 | E11: 中国移动广东公司-2024-2025年电子渠道H5属地化营销支撑采购项目-FP项目 | F11: 0.2057 | G11: 0.1081 | H11: 0.08157676 | I11: -0.0885 | T11: 0.094573018 | U11: 0.085810187 | AF11: 0.075912016 | AG11: -0.097381821 | AR11: 0.080318428 | AS11: 0.071811996 | BD11: =U11-F11 -> -0.11988981 | BE11: =AS11-G11 -> -0.036288004 | BF11: =_xlfn.IFS(BD11<-3%,"不达标",BD11<0%,"基本达标",TRUE,"达标") -> 不达标 | BG11: 低 | BH11: 之前立项时未将分包收入支出单独立项，产出存在超报。 | BI11: 需调整产出保证数据据实。 | BL11: 1、2月最后一个月冲抵且2月离职2人，成本下降到11万，3月毛利回正预估8%。 2、分包金额70万因项目周期拉长，需重新计算，由原来70万变更成38万，剩眄32万分包收入毛利合至本项目，待商务变更后，走项目变更，预计毛利为15% | BV11: 0.1759 | BW11: 计划减少5个人（AI提效2-3个人，需求少了2个人）1月底走2个 2月底走2个，3月份8个人，4月底1个人。
A12: =VLOOKUP(D12,Sheet10!A:B,2,0) -> 电信联通综合事业部 | B12: 45758 | C12: 46112 | D12: P202504000324 | E12: 山东移动-2025-山亭区城市大脑平台一期ICT信息和通信系统信息化服务协议-城市大脑FP项目 | F12: 0.2166 | G12: 0.1891 | H12: 0 | T12: 0.4814 | AF12: 0 | AR12: 0.4738 | BD12: =U12-F12 -> -0.2166 | BE12: =AS12-G12 -> -0.1891 | BF12: =_xlfn.IFS(BD12<-3%,"不达标",BD12<0%,"基本达标",TRUE,"达标") -> 不达标 | BG12: 低 | BH12: 4月新立项目处于爬坡期，需求分析阶段交付进度偏低，交付进度低于成本完工进度 | BI12: 进入开发阶段进度追赶后预计毛利率可恢复正常
A13: =VLOOKUP(D13,Sheet10!A:B,2,0) -> 泛AIoT与设备商事业部 | B13: 45774 | C13: 46387 | D13: P202505000063 | E13: 天府再生资源-2025-2027年云平台建设服务合同-FP项目 | F13: 0.1542 | G13: 0.1542 | H13: -0.0279 | I13: 0.4461 | T13: 0.0699 | U13: 0.1489 | AF13: -0.0319 | AG13: 0.4438 | AR13: 0.0673 | AS13: 0.1463 | BD13: =U13-F13 -> -0.0053 | BE13: =AS13-G13 -> -0.0079 | BF13: =_xlfn.IFS(BD13<-3%,"不达标",BD13<0%,"基本达标",TRUE,"达标") -> 基本达标 | BG13: 高 | BH13: 1、为赶进度12月下旬开始增加4名外接开发人员，投入成本增加7w多，毛利拉低， 2、存在甲方客户负责人变更，对需求优先级调整，整体交付进度缓慢。 3、3名闲置人员的成本挂在本项目 | BI13: 预计外借的4名开发人员持续投入到26年3月底，进度追赶正常后，结束投入。 | BJ13: 1、为赶进度12月下旬人员投入成本增多2.3w，毛利拉低，预计人员持续投入到26年3月底，后续减少人员投入。 2、当月进度填报偏差，系统进度40%，实际进度43%，GP1%毛利15.8%，1月纠偏 | BK13: 等借调人员投入结束后，预计3月毛利恢复正常，整体测算毛利可达标
A14: 电信联通综合事业部 | B14: 45809 | C14: 46171 | D14: P202506000764 | E14: 中移物联网-2025年贵州省仁怀酱酒集团智慧园区项目二期-FP项目 | F14: 0.2208 | G14: 0.141 | H14: 0 | T14: 0.191 | AF14: 0 | AR14: 0.1829 | BD14: =U14-F14 -> -0.2208 | BE14: =AS14-G14 -> -0.141 | BF14: =_xlfn.IFS(BD14<-3%,"不达标",BD14<0%,"基本达标",TRUE,"达标") -> 不达标 | BG14: 低 | BH14: 6月新立项目，客户要求7月内完成交付和验收工作，前两月冲进度，投入人力成本进度高于填报进度 | BI14: 预计7月中旬后主要交付工作完成，人力投入大幅缩减，毛利率可逐步拉升至正常水平
A15: 电信联通综合事业部 | B15: 45658 | C15: 46265 | D15: / | E15: 中移信息项目群（当前1个在行项目） | F15: 0.16 | G15: 0.16 | H15: -0.1212 | I15: 0.9972 | T15: 0.0569 | U15: -0.0484 | AF15: -0.1291 | AG15: 0.9671 | AR15: 0.0433 | AS15: -0.0533 | BD15: =U15-F15 -> -0.2084 | BE15: =AS15-G15 -> -0.2133 | BF15: =_xlfn.IFS(BD15<-3%,"不达标",BD15<0%,"基本达标",TRUE,"达标") -> 不达标 | BG15: 低 | BH15: 1、P202501000294项目在8月超报收入回冲135w； 2、七期合同8月才启动，产出爬坡阶段，持续投入可达成毛利目标 3、七期项目产出进度填报偏差 | BI15: 预计2026/3月开票验收，剩余产出会全部报出，毛利恢复正常 | BJ15: 七期项目产出进度填报偏差，预计3月开票验收，剩余产出会全部报出，毛利恢复正常 | BK15: 25年的产出进度填报偏差较大，预计2026/4月七期开票验收，剩余产出会全部报出，毛利恢复正常
A16: 电信联通综合事业部 | B16: 45901 | C16: 46266 | D16: P202509000650 | E16: 中移物联网-2025年浦林成山轮胎X光智能检测项目-FP项目 | F16: 0.1587 | G16: 0.2165 | H16: 0.0795 | T16: -0.1088 | AF16: 0.0764 | AR16: -0.1152 | BD16: =U16-F16 -> -0.1587 | BE16: =AS16-G16 -> -0.2165 | BF16: =_xlfn.IFS(BD16<-3%,"不达标",BD16<0%,"基本达标",TRUE,"达标") -> 不达标 | BG16: 低 | BH16: 11月NoPO超期合同未签回，收入回冲；12月底合同签回，金额调整为65.1万，重新报批毛利率目标为38%左右，系统内成本进度填报偏低导致偏差，预计整体毛利率目标可达成 | BI16: / | BJ16: 截止12月底交付工作已基本完成，预计后续少量投入，系统内成本进度填报偏低导致偏差，预计整体毛利率目标可达成 | BK16: 截止12月底交付工作已基本完成，预计后续少量投入，系统内成本进度填报偏低导致偏差，预计整体毛利率目标可达成
A17: 电信联通综合事业部 | B17: 45901 | C17: 46266 | D17: P202509000455 | E17: 中电建成都院-2025年（深开鸿）中电建成都院振冲碎石桩鸿蒙化改造项目（一期）-FP项目 | F17: 0.1663 | G17: 0.1663 | H17: 0 | T17: 0.2669 | AF17: 0 | AR17: 0.2624 | BD17: =U17-F17 -> -0.1663 | BE17: =AS17-G17 -> -0.1663 | BF17: =_xlfn.IFS(BD17<-3%,"不达标",BD17<0%,"基本达标",TRUE,"达标") -> 不达标 | BG17: 低 | BH17: 9月底新立项目，系统计算收入偏差所致，按实际完工进度收入测算毛利率为35%，全周期毛利率16.63%可达成目标
A18: 电信联通综合事业部 | B18: 45901 | C18: 46265 | D18: P202509000597 | E18: 中移物联网-2025-2026年杭州滨江物联网运维二期项目-FP项目 | F18: 0.1816 | G18: 0.184 | H18: 0 | T18: 0.3655 | AF18: 0 | AR18: 0.3618 | BD18: =U18-F18 -> -0.1816 | BE18: =AS18-G18 -> -0.184 | BF18: =_xlfn.IFS(BD18<-3%,"不达标",BD18<0%,"基本达标",TRUE,"达标") -> 不达标 | BG18: 低 | BH18: 9月底新立项目，启动初期进度填报偏差所致，按实际完工进度收入测算9月毛利率为35.75%，全周期项目GP3毛利率为19.61%
A19: 泛AIoT与设备商事业部 | B19: 45689 | C19: 46203 | D19: P202601000361 | E19: 河南巴洛克-2026-2027年中航光电科技股份全球运营中心软件平台-FP项目 | F19: 0.24 | G19: 0.24 | H19: 0.2799 | I19: -0.0342 | T19: 0.2799 | U19: 0.1296 | AF19: 0.2788 | AG19: -0.0753 | AR19: 0.2788 | AS19: 0.1094 | BD19: =U19-F19 -> -0.1104 | BE19: =AS19-G19 -> -0.1306 | BF19: =_xlfn.IFS(BD19<-3%,"不达标",BD19<0%,"基本达标",TRUE,"达标") -> 不达标 | BG19: 低 | BH19: 3/13 交付进度填报偏差，系统进度填报42%，低于成本进度56%，导致毛利低于预算 | BI19: 3月报产追回交付进度 | BL19: 3月报产追回交付进度
A20: 泛AIoT与设备商事业部 | B20: 45689 | C20: 46387 | D20: P202601000058 | E20: 成都鼎桥-2026年ICP框架-ICS&警务协同委托开发-FP项目 | F20: 0.2261 | G20: 0.18 | H20: 0.2514 | I20: 0.1418 | T20: 0.2514 | U20: 0.1801 | AF20: 0.2503 | AG20: 0.0884 | AR20: 0.2503 | AS20: 0.145 | BD20: =U20-F20 -> -0.046 | BE20: =AS20-G20 -> -0.035 | BF20: =_xlfn.IFS(BD20<-3%,"不达标",BD20<0%,"基本达标",TRUE,"达标") -> 不达标 | BG20: 低 | BH20: 3/13 交付进度填报偏差 | BI20: 3月报产追回交付进度 | BL20: 3月报产追回交付进度
A21: 移动研究院事业部 | B21: 46023 | C21: 46387 | D21: P202601001254 | E21: 中免海南-2026年一站通项目系统开发服务项目-FP项目 | F21: 0.1815 | G21: 0.1815 | H21: 0.38255096 | I21: -0.28329472 | T21: 0.38255096 | U21: 0.051634168 | AF21: 0.38148291 | AG21: -0.28594153 | AR21: 0.38148291 | AS21: 0.049781493 | BD21: =U21-F21 -> -0.12986583 | BE21: =AS21-G21 -> -0.13171851 | BF21: 不达标 | BG21: 低 | BH21: 2月产出 报少 | BI21: 1、根据项目实际进度填报产出 3、每月根据项目情况，对项目排产计划及进度计划进行审视，控制当前人力成本。

Sheet Sheet10
A1: 项目编码
A2: P202308000487 | B2: 移动研究院事业部
A3: P202505000350 | B3: 移动研究院事业部
A4: P202505000354 | B4: 泛AIoT与设备商事业部
A5: P202408001384 | B5: 电信联通综合事业部
A6: P202505000533 | B6: 电信联通综合事业部
A7: P202504001053 | B7: 电信联通综合事业部
A8: P202501000294 | B8: 电信联通综合事业部
A9: P202501000196 | B9: 电信联通综合事业部
A10: P202412000771 | B10: 泛AIoT与设备商事业部
A11: P202408001430 | B11: 电信联通综合事业部
A12: P202501000238 | B12: 电信联通综合事业部
A13: P202504000876 | B13: 泛AIoT与设备商事业部
... A1593: P202411000666 | B1593: 移动研究院事业部

Sheet 合同毛利率
A1: 项目编码 | B1: 合同评审流水号 | C1: 预计毛利率（%）
A2: P202412000616 | B2: RR202501160007 | C2: #N/A
A3: P202509000369 | B3: RC20250910001000 | C3: 19.67
A4: P202510000605 | B4: RC20250910001000 | C4: 19.67
A5: P202509000649 | B5: RC20250918001014 | C5: 8.06
A6: P202602000041 | B6: RR20260303001009 | C6: 28.89
A7: P202602000119 | B7: RR20260224001000 | C7: #N/A
A8: P202601001382 | B8: RR20260224001000 | C8: #N/A
A9: P202603000003 | B9: RR20260224001000 | C9: #N/A
A10: P202603000004 | B10: RR20260224001000 | C10: #N/A
A11: P202603000001 | B11: RC20260122001013 | C11: 1.2
A12: P202504001360 | B12: RC20250423001011 | C12: 21.56
A13: P202507000410 | B13: RC20250423001011 | C13: 21.56
A14: P202601000585 | B14: RC20260116001026 | C14: 32.15
A15: P202601000586 | B15: RC20260116001026 | C15: 32.15
A16: P202601000587 | B16: RC20260116001026 | C16: 32.15
A17: P202601000588 | B17: RC20260116001026 | C17: 32.15
A18: P202601000589 | B18: RC20260116001026 | C18: 32.15
A19: P202601000590 | B19: RC20260116001026 | C19: 32.15
A20: P202601000591 | B20: RC20260116001026 | C20: 32.15
A21: P202601000592 | B21: RC20260116001026 | C21: 32.15
A22: P202602000164 | B22: RC20260116001026 | C22: 32.15
... A27: P202602000169 | B27: RC20260116001026 | C27: 32.15
A28: P202602000251 | B28: RC20260115001014 | C28: #N/A
A29: P202506000455 | B29: RR20260209001009 | C29: 12.02
A30: P202506000545 | B30: RR20260209001009 | C30: 12.02
A31: P202602000193 | B31: RC20260204001011 | C31: 18.5
A32: P202602000194 | B32: RC20260204001011 | C32: 18.5
A33: P202307000135 | B33: RC202306090001 | C33: #N/A
A34: P202503000437 | B34: RR20250818001000 | C34: 13.07
A35: P202601001259 | B35: RC20260130001004 | C35: 17.91
A36: P202601001263 | B36: RC20260130001004 | C36: 17.91
A37: P202601001264 | B37: RC20260130001004 | C37: 17.91
A38: P202601001266 | B38: RC20260130001004 | C38: 17.91
A39: P202512000053 | B39: RC20251119001003 | C39: 5
A40: P202512000054 | B40: RC20251119001003 | C40: 5
A41: P202602000070 | B41: RR20250715001009 | C41: 18.1
A42: P202511000501 | B42: RC20251120001000 | C42: 10.25
A43: P202512000398 | B43: RC20251120001000 | C43: 10.25
A44: P202601000547 | B44: RC20251120001000 | C44: 10.25
...

Sheet 在行假FP项目毛利率达标偏差分析
A2: 在行假FP项目毛利率达标分析
A3: 事业部 | B3: 项目开始时间 | C3: 项目结束时间 | D3: 项目编码 | E3: 项目名称 | F3: 报价毛利率 | G3: 项目立项毛利率 | H3: 当月毛利率-GP1% | T3: YTD毛利率-GP1% | AF3: 当月毛利率-GP3% | AR3: YTD毛利率-GP3% | BD3: 差距-GP1% | BE3: 差距-GP3% | BF3: 毛利达标-GP1% | BG3: 风险 | BH3: 不达标原因，看GP1%和GP3% | BI3: 措施 | BJ3: 202601月进展 | BK3: 202602月进展 | BL3: 202603月进展 | BM3: 202604月进展 | BN3: 202605月进展 | BO3: 202606月进展 | BP3: 202607月进展 | BQ3: 202608月进展 | BR3: 202609月进展 | BS3: 202610月进展 | BT3: 202611月进展 | BU3: 202612月进展 | BV3: 系统立项GP1
H5: 1月 | I5: 2月 | J5: 3月 | K5: 4月 | L5: 5月 | M5: 6月 | N5: 7月 | O5: 8月 | P5: 9月 | Q5: 10月 | R5: 11月 | S5: 12月 | T5: 1月 | U5: 2月 | V5: 3月 | W5: 4月 | X5: 5月 | Y5: 6月 | Z5: 7月 | AA5: 8月 | AB5: 9月 | AC5: 10月 | AD5: 11月 | AE5: 12月 | AF5: 1月 | AG5: 2月 | AH5: 3月 | AI5: 4月 | AJ5: 5月 | AK5: 6月 | AL5: 7月 | AM5: 8月 | AN5: 9月 | AO5: 10月 | AP5: 11月 | AQ5: 12月 | AR5: 1月 | AS5: 2月 | AT5: 3月 | AU5: 4月 | AV5: 5月 | AW5: 6月 | AX5: 7月 | AY5: 8月 | AZ5: 9月 | BA5: 10月 | BB5: 11月 | BC5: 12月
A6: 泛AIoT与设备商事业部 | B6: 45931 | C6: 46326 | D6: P202510000728 | E6: 长安汽车-2025-2026年CADDM领域级指标一阶段升级项目-FP项目 | G6: 0.0881 | H6: -0.8837 | I6: 0.05944874 | T6: -0.0418 | U6: -0.019280727 | AF6: -0.8912 | AG6: 0.05464259 | AR6: -0.0447 | AS6: -0.022609613 | BD6: =U6-F6 -> -0.019280727 | BE6: =AS6-G6 -> -0.11070961 | BF6: =_xlfn.IFS(BD6<-3%,"不达标",BD6<0%,"基本达标",TRUE,"达标") -> 基本达标 | BG6: 低
A7: 电信联通综合事业部 | B7: 45931 | C7: 46022 | D7: P202510000603 | E7: 中移湾区-2025-2026年通用类软件设计与构建支撑服务框架协议（有线巡检平台项目）-TM项目 | F7: 0.1852 | G7: 0.1852 | BD7: =U7-F7 -> -0.1852 | BE7: =AS7-G7 -> -0.1852 | BF7: =_xlfn.IFS(BD7<-3%,"不达标",BD7<0%,"基本达标",TRUE,"达标") -> 不达标 | BG7: 低
A8: 电信联通综合事业部 | B8: 45931 | C8: 46022 | D8: P202510000604 | E8: 中移湾区-2025-2026年通用类软件支撑服务框架-水利厅TM项目 | F8: 0.2265 | G8: 0.2265 | BD8: =U8-F8 -> -0.2265 | BE8: =AS8-G8 -> -0.2265 | BF8: =_xlfn.IFS(BD8<-3%,"不达标",BD8<0%,"基本达标",TRUE,"达标") -> 不达标 | BG8: 低
A9: 电信联通综合事业部 | B9: 45962 | C9: 46022 | D9: P202511000048 | E9: 中移湾区-2025-2026年通用类软件支撑服务框架-数据可信BI项目TM项目 | F9: 0.185 | G9: 0.185 | BD9: =U9-F9 -> -0.185 | BE9: =AS9-G9 -> -0.185 | BF9: =_xlfn.IFS(BD9<-3%,"不达标",BD9<0%,"基本达标",TRUE,"达标") -> 不达标 | BG9: 低
A10: 电信联通综合事业部 | B10: 45962 | C10: 46142 | D10: P202511000346 | E10: 中移湾区-2025-2026年通用类软件支撑服务框架-数据脱敏TM项目 | F10: 0.2398 | G10: 0.154 | BD10: =U10-F10 -> -0.2398 | BE10: =AS10-G10 -> -0.154 | BF10: =_xlfn.IFS(BD10<-3%,"不达标",BD10<0%,"基本达标",TRUE,"达标") -> 不达标 | BG10: 低
A11: 电信联通综合事业部 | B11: 45992 | C11: 46081 | D11: P202512000266 | E11: 中移湾区-2025-2026年通用类软件支撑服务框架-灵犀九天鸿蒙APPTM项目 | F11: 0.1871 | G11: 0.1871 | BD11: =U11-F11 -> -0.1871 | BE11: =AS11-G11 -> -0.1871 | BF11: =_xlfn.IFS(BD11<-3%,"不达标",BD11<0%,"基本达标",TRUE,"达标") -> 不达标 | BG11: 低
A12: 电信联通综合事业部 | B12: 45992 | C12: 46173 | D12: P202512000267 | E12: 中移湾区-2025-2026年通用类软件支撑服务框架-数据安全保障TM项目 | F12: 0.2515 | G12: 0.154 | BD12: =U12-F12 -> -0.2515 | BE12: =AS12-G12 -> -0.154 | BF12: =_xlfn.IFS(BD12<-3%,"不达标",BD12<0%,"基本达标",TRUE,"达标") -> 不达标 | BG12: 低
A13: 泛AIoT与设备商事业部 | B13: 45658 | C13: 46022 | D13: P202501001105 | E13: 成都鼎桥-2023-2025年ICP框架-UMP委托开发2025-FP项目 | F13: 0.2368 | G13: 0.2477 | H13: 1 | T13: 0.2897 | AF13: 2.9111 | AR13: 0.2828 | BD13: =U13-F13 -> -0.2368 | BE13: =AS13-G13 -> -0.2477 | BF13: =_xlfn.IFS(BD13<-3%,"不达标",BD13<0%,"基本达标",TRUE,"达标") -> 不达标 | BG13: 低 | BH13: 项目暂停
A14: 泛AIoT与设备商事业部 | B14: 45658 | C14: 46022 | D14: P202501001101 | E14: 成都鼎桥-2023-2025年ICP框架-WebDC-MCX委托开发2025-FP项目 | F14: 0.2368 | G14: 0.2477 | H14: 0 | T14: 0.4408 | AF14: 0 | AR14: 0.4343 | BD14: =U14-F14 -> -0.2368 | BE14: =AS14-G14 -> -0.2477 | BF14: =_xlfn.IFS(BD14<-3%,"不达标",BD14<0%,"基本达标",TRUE,"达标") -> 不达标 | BG14: 低 | BH14: 转切TM 1~2月项目需求尚未形成基线，需求变更较频繁，因此产出进度填报偏少，按照计划TR4过点后季度结算确认金额后，产出填报补回之前少报部分，预计4月之后逐步追回毛利 | BI14: 5/10 自4月起转为TM项目合作模式，当前毛利偏差部分正在通过与客户沟通补充工作量的方式逐步弥补
A15: 泛AIoT与设备商事业部 | B15: 46023 | C15: 46081 | D15: P202601001343 | E15: 成都鼎桥-2026年ICP框架-山东黄金委托开发三期-FP项目 | G15: 0.187803 | H15: 0.10415766 | I15: 0.088306081 | T15: 0.10415766 | U15: 0.098371832 | AF15: 0.10308962 | AG15: 0.085379955 | AR15: 0.10308962 | AS15: 0.096625593 | BD15: =U15-F15 -> 0.098371832 | BE15: =AS15-G15 -> -0.091177403 | BF15: 不达标
A16: 泛AIoT与设备商事业部 | B16: 46023 | C16: 46203 | D16: P202512000528 | E16: 北京励鼎-2026车衣&玻璃膜项目系统开发支持项目-FP项目 | G16: 0.18594442 | H16: 0.15846417 | I16: 0.014222098 | T16: 0.15846417 | U16: 0.092324647 | AF16: 0.15739612 | AG16: 0.090678279 | AR16: 0.15739612 | AS16: 0.011892816 | BD16: =U16-F16 -> 0.092324647 | BE16: =AS16-G16 -> -0.17405161 | BF16: 不达标 | BG16: 低
A17: 泛AIoT与设备商事业部 | B17: 46023 | C17: 46387 | D17: P202601001110 | E17: 理想汽车-2026工厂老化和电检测试系统开发项目-FP项目 | G17: 0.20821784 | H17: 0.28856312 | I17: 0.20195314 | T17: 0.28856312 | U17: 0.26401568 | AF17: 0.28749517 | AG17: 0.19818483 | AR17: 0.28749517 | AS17: 0.26218238 | BD17: =U17-F17 -> 0.26401568 | BE17: =AS17-G17 -> 0.053964546 | BF17: 达标 | BG17: 无
A18: 泛AIoT与设备商事业部 | B18: 45855 | C18: 46387 | D18: P202508000030 | E18: 行致互联-2025年车主APP鸿蒙开发三期-FP项目 | G18: 0.17679647 | H18: 1 | I18: 收入成本为0 | T18: 0.52364605 | U18: 0.52364605 | AF18: 0.99067891 | AG18: 收入成本为0 | AR18: 0.5204706 | AS18: 0.51976453 | BD18: =U18-F18 -> 0.52364605 | BE18: =AS18-G18 -> 0.34296806 | BF18: 达标 | BG18: 无
A19: 泛AIoT与设备商事业部 | B19: 45855 | C19: 46387 | D19: P202508000034 | E19: 行致互联-2025年车主APP鸿蒙开发二期-FP项目 | G19: 0.18423525 | H19: 1 | I19: 收入成本为0 | T19: 0.37198247 | U19: 0.37198247 | AF19: 0.99645515 | AG19: 收入成本为0 | AR19: 0.36968039 | AS19: 0.36897126 | BD19: =U19-F19 -> 0.37198247 | BE19: =AS19-G19 -> 0.18473601 | BF19: 达标 | BG19: 无
A20: 泛AIoT与设备商事业部 | B20: 45855 | C20: 46219 | D20: P202507000892 | E20: 行致互联-2025年车主APP鸿蒙开发-FP项目 | G20: 0.18056152 | H20: 1 | I20: 收入成本为0 | T20: 0.32168216 | U20: 0.37360601 | AF20: 0.9933821 | AG20: 收入成本为0 | AR20: 0.31990421 | AS20: 0.37144787 | BD20: =U20-F20 -> 0.37360601 | BE20: =AS20-G20 -> 0.19088635 | BF20: 达标 | BG20: 无
A21: 泛AIoT与设备商事业部 | B21: 46054 | C21: 46234 | D21: P202602000029-(假FP） | E21: 理想-2026年用户运营系统专项需求-FP项目 | G21: 0.15885571 | H21: / | I21: -0.13418187 | T21: / | U21: -0.13418187 | AF21: / | AG21: -0.13525001 | AR21: / | AS21: -0.13525001 | BD21: =U21-F21 -> -0.13418187 | BE21: =AS21-G21 -> -0.29410572 | BF21: 达标

Sheet 结项项目毛利率达标偏差分析
A2: 已结项目毛利率达标分析
A3: 事业部 | B3: 项目开始时间 | C3: 项目结束时间 | D3: 项目编码 | E3: 项目名称 | F3: 项目立项毛利率 | G3: 结项毛利率 | H3: 毛利达标 | I3: 不达标原因 | J3: 措施及进展
A4: 电信联通综合事业部 | B4: 45566 | C4: 46054 | D4: P202502000351 | E4: 用友-2025年铁塔视联平台开发外包项目-FP项目 | F4: 0.1516 | G4: -1.8891 | H4: 不达标 | I4: 铁塔项目拉通看：用友-2024-2025年铁塔能源低速充电平台开发外包项目-FP项目、用友-2024-2025年铁塔AIOT平台开发外包项目-FP项目、用友-2025年铁塔视联平台开发外包项目-FP项目、中国铁塔-2024年IT开发能力服务合同框架-PMS系统FP项目。毛利未达标原因：因25年铁塔未中标，涉及提前投入的280万产出回冲。 | J4: 铁塔2025年PMS交付工作量未结算，收入未计入，计划2026年重新中标后补结算
A5: 泛AIoT与设备商事业部
A6: 移动研究院事业部
A7: =VLOOKUP(D7,Sheet10!A:B,2,0) -> 泛AIoT与设备商事业部 | B7: 45689 | C7: 46022 | D7: P202502000280 | E7: 史密斯-2025年非生产采购框架-定制开发FP项目 | F7: 0.229 | G7: 0.20426083 | H7: =_xlfn.IFS(F7<-3%,"不达标",F7<0%,"基本达标",TRUE,"达标") -> 达标 | I7: 史密斯项目为框架+订单模式，由于25年订单减少，人员与鼎桥MCX、UMP进行复用，产出需要拉统4个项目统一审视，整体还原毛利为GP1 18.8%，后续产出会持续在鼎桥项目上调增，拉通毛利达标，项目包括（P202502000280 史密斯/P202311000693 UMP委托开发2023-2024/P202501001105 UMP委托开发2025/P202501001101 MCX委托开发）
A8: 泛AIoT与设备商事业部 | B8: 45931 | C8: 46022 | D8: P202504000647 | E8: 理想汽车-2024-2026年罗克维尔斯智能商业开发委托协议ODC-2025Q4-FP项目 | F8: 0.1808 | G8: 0.13692875 | H8: =_xlfn.IFS(F8<-3%,"不达标",F8<0%,"基本达标",TRUE,"达标") -> 达标 | I8: 项目从10开始再无新发包，当前ODC项目完成存量业务后，项目结项，产出据实上报
A9: =VLOOKUP(D9,Sheet10!A:B,2,0) -> 电信联通综合事业部 | B9: 45313 | C9: 46071 | D9: P202401000839 | E9: 南京大数据_烟道阻火灭火城市鸿蒙试点场景建设项目2024-2026-FP项目
A10: 移动研究院事业部 | B10: 45852 | C10: 46081 | D10: P202507000256 | E10: 常熟酒业-碰碰杯地域性SaaS系统开发项目-FP | F10: 0.2004 | G10: 0.0629 | H10: 不达标 | I10: 上线后试运行2个月的成本未在预算中评估，导致成本超预算； | J10: 3/13 洽谈下一期合同金额的时候，会同客户协商将此部分金额涵盖
A11: 电信联通综合事业部 | B11: 45931 | C11: 46081 | D11: P202510000605 | E11: 中电智科-2025-2027年研发支撑服务项目技术服务框架协议-FP项目 | F11: 0.1967 | G11: 0.1343 | H11: 不达标 | I11: 预估的工作量上报后被客户核减，预估结项毛利有5%左右，实际结项毛利13%。

Sheet 毛利评审会议纪要
A1: FP项目运营分析会遗留问题
A2: 事业部 | B2: 项目名称 | C2: 问题描述 | D2: 应对措施描述 | E2: 提出时间 | F2: 责任人 | G2: 计划完成时间 | H2: 实际完成时间 | I2: 当前状态 | J2: 进展
A3: 电信联通综合事业部 | B3: 翼支付-2024-2025年农垦Tob电商研发项目-FP项目 | C3: 【合同风险】：上一期项目NoPO合同未拿回，导致项目挂起重新立项，该新项目承诺25年8月签回合同 | D3: 【措施】近期的措施是：要延期合同拿回时间，推动樊总批流程； 长期的措施是：推动销售签署合同 | E3: 45735 | F3: 李剑锋 李大浩（销售侧） | G3: 45899 | I3: 关闭 | J3: 8.14 合同拿回时间延期到12/30 7.31 廖总已审批完，合同延期。 7.10 客户已完成采购流程，预计一周内挂网招标 6.19 月底启动招投标；合同延期有待推动报批 6/5 客户内部立项6月底招投标，邮件申请合同延期找宇总审批到廖总。 4.17 客户发起立项流程，预计5月进行第一轮招投标预计300w。24年客户欠160w合计25年共200w左右，通过中电智恒过单。
A4: 电信联通综合事业部 | B4: 深开鸿-2024-2026年JH第一批次项目-FP项目 | C4: 【合同风险】该项目AIG作为总集方与深开鸿合同未签订，原承诺2月内签回现延迟到3月份，导致内部分包给解决方案业务部项目被挂起收入计0 | D4: 【措施】跟进AIG与深开鸿签约进展 | E4: 45735 | F4: 沙建银（交付侧） 刘贺（销售侧） | G4: 45777 | I4: 关闭 | J4: 5.13 合同已拿回上传系统。 4.29AIG侧反馈最新进展，与开鸿合同拿回日期延后到5.30，日期变更申请已邮件报廖总审批通过。
A5: 电信联通综合事业部 | B5: 数字重庆-2024观音桥商圈领导驾驶舱- FP项目 | C5: 【合同风险】项目为NoPO立项，立项承诺合同签署日期为2024.11.15，当前合同尚未签订 | D5: 【措施】问题已纳入部门重点跟踪事项，由项目经理整理验收报告后协同销售侧找客户签字 | E5: 45735 | F5: 沙建银（交付侧） 张先建（销售侧） | G5: 45807 | I5: 关闭 | J5: 9.19 运营审视会上沙哥已确认合同已签订待回款。 7.31 暂无进展 7.10 新销售赵肖飞待述职后去重庆沟通。 6.19 项目经理与客户对接，客户无响应，待求助上升集团 6.4 销售张先建已离职，待新销售交接后找新销售对接。 4.28 销售侧张先建反馈合同最快4月内，最晚5月内可以签回
A6: 移动研究院事业部 | B6: 重庆数字陆海新通道门户及驾驶舱建设项目 | C6: NoPO项目合同风险，当前甲方内部对项目建设成本出处有争议，项目金额缩减的风险很高，合同拿回风险也很高，需要销售侧强力推动 | D6: 关于重庆数字陆海项目nopo金额大，合同风险高的问题，会后由沙建银将项概要情况整理发大勇总，由大勇总帮忙上升至集团层面重点跟进 | E6: 45763 | F6: 万成林 | G6: 45763 | I6: 打开 | J6: 会后已由沙建银整理项目概况发送大勇总在集团层面跟进；3月底项目负责人黄海博去重庆与中移集成负责人做了线下沟通，客户负责人承诺会将项目预算的事情专门去跟重庆移动做一次沟通，明确一期费用和二期项目建设内容后再会给我们答复。目前我方现场支撑人力已撤出，在相关问题未明确前暂停投入。
A7: 泛AIoT与设备商事业部 | B7: 理想汽车-2024-2026年罗克维尔斯智能商业开发委托协议ODC-FP项目 | C7: 关于项目发包不稳定项目断档导致的产出不足，闲置成本增加问题，如何通过销售资源配置从销售入口寻求改善项目经营情况 | D7: 会后讨论是否可以通过增加销售资源和拓宽销售入口来看一看理想有没有其它业务机会，帮这个项目团队多找补一些需求 | E7: 45763 | F7: 大勇总 任永涛 侯黎明 | G7: 45838 | I7: 关闭 | J7: 4月初根据需求情况调整人力规模到32人，①根据项目排产情况提前规划人力跨项目投入，减少成本损耗，根据产出任务完成情况考核人员投入工作量，取消周末加班上报。②在常州本地投入驻场人员，减少出差，降低成本。③下订单后根据交付计划签署短期用工合同，减少后期闲置成本。④面向理想采购人员积极沟通争取其他定制类项目，当前挖掘AI需求一个，待报价。4月中标7个订单（总11个），金额190W，产能提升，根据订单进度4月GP1提升到20%。
A8: 电信联通综合事业部 | B8: 南京大数据_烟道阻火灭火城市鸿蒙试点场景建设项目2024-2026-FP项目 | C8: 前期部分售前解决方案人力工时填报在项目上导致成本超出，关于售前解决方按协助其他BG和销售组织支撑售前活动相关的人力工时和差旅成本，目前都是解决方案组织内部找项目解决，需要明确合理的成本分摊机制 | D8: 由李剑锋、汤华兴讨论明确售前解决方案支撑场景与相关成本分摊规则，原则上讲：对于打单成功的合同，项目落到哪个交付单元售前成本就由哪个单元承担，打单没中的要明确一个售前成本分摊规则，规则确定后提交晓宇总和顾总审议通过，出个规范正式发文出来，以后按规范执行；对于售前解决方案支撑部门来说，要做好商机的筛选和初审，评判和选择有价值高成功率的商机去投入 | E8: 45763 | F8: 李剑锋、汤华兴讨论明确规则，晓宇总、顾总审议通过后执行 | G8: 45838 | I8: 关闭 | J8: 6.19 已落地 5.22 措施落地效果待审视 4.28电信解决方案与销售部月度联席会议上晓宇总、李剑锋及沙建银与销售部顾总、子琦总就该问题做了讨论，初步形成了共识，售前成本归属到对应项目，商机出现如需要输出解决方案和出差支撑客户现场交流的，由对应销售提前邮件向子琦总和顾总报批，根据商机价值和成功概率内部评估可行后再提供成本编码给解决方案做成本填报。
A9: 电信联通综合事业部 | B9: 1.陕西高法大运维项目 2.陕西消防-2024-2025年电动自行车安全专项整治工作系统-FP项目 3.深圳光明区-2024-2025年鸿蒙物联网平台-鸿蒙FP项目 三个丢单高风险NoPO项目 | C9: 【合同风险】3个高风险NoPO项目，合同超过承诺日期未签回，当前销售侧反馈大概率丢单，相关收入已回冲，已投入成本要与销售侧明确分摊机制 | D9: 【措施】 1、整理3个项目情况，纳入与AIG沟通议题，与AIG明确沉没成本分摊事宜； 2、完善NoPO立项审批机制，明确要求：对于跨集团的NoPO项目立项合作交付，必须在立项申请邮件中明确和约定清楚，假如将来丢标或者金额缩减的话，沉没成本如何分摊的问题（销售组织和交付组织对半分摊还是怎样？）如果是集团内部的NoPO项目发生上述情况，那就是谁申请的NoPO谁负责承担成本； 3、完善NoPO商机评审机制，输出NoPO商机风险评估Checklist，满足哪些条件，综合评估多高概率才可以决策NoPO提前投入，有明确的决策上升机制，根据标的金额、售前投入金额不同上升到不同的层级进行决策，降低盲目投入风险。 | E9: 45826 | F9: 大勇总 晓宇总 李剑锋 沙建银 | G9: 45856 | I9: 关闭 | J9: 9.24 项目授权成本分摊方案初稿完成，需要和各周边部门评审后再在集团汇报 7.31 成本分摊，还需与ABG确认。 7.10 与AIG分摊成本。NOPO相关机制已输出 6.19 解决方案团队已梳理形成商机评估因素Checklist，会后发出并拉通销售组织一起讨论完善并形成执行规范；
A10: 电信联通综合事业部 | B10: 使用AIGC工具在解决方案业务场景中进一步探索和推广降本增效 | C10: 鸿蒙生态皋春明团队已在项目开发中使用AI编码辅助工具做了使用，会后拉通解决方案团队，组织一次分享，然后找合适项目做尝试并进一步推广 | D10: 【措施】会后拉通皋春明约时间组织一次分享 | E10: 45826 | F10: 沙建银 | G10: 45838 | I10: 关闭 | J10: 6.24 双方已拉会组织分享交流
A11: 电信联通综合事业部 | B11: 农业项目 | C11: 1.农业项目整体核算，结果发给大勇总 2.商机阶段人力投入问题讨论（大勇总、汤总、老沙、白） | E11: 45888 | F11: 沙建银（交付侧） 大勇总 汤总 | G11: 45894 | I11: 关闭 | J11: 1.农业项目整体结果已经发给大勇总 2.8/21 已完成商机阶段的人力投入问题讨论
A12: 泛AIoT与设备商事业部 | B12: 华勤测试项目 | C12: 华勤项目是否能够和泛终端的ODM项目形成人力共用 | E12: 45888 | F12: 路学海 老白 | G12: 45894 | I12: 关闭 | J12: 8/20 已完成
A13: 泛AIoT与设备商事业部 | B13: 1.长安汽车-2024-2025年CADDM指标在线分析及优化项目-FP项目 2、长安汽车-2025年企业数字化需求管理系统项目 | C13: 1.长安汽车-2024-2025年CADDM指标在线分析及优化项目-FP项目结项后做好人力安置，下次会议讲一下人员去向 2、长安汽车-2025年企业数字化需求管理系统项目技术服务合同-FP项目 尽最大可能保证项目交付的前提下做好成本管控，争取改善运营结果 | D13: CADDM项目讲一下人员后续调整去向 | E13: 45888 | F13: 侯黎明 | G13: 45910 | I13: 关闭 | J13: 10.29 9月运营损益单月已回正，CADDM项目已结项，需求管理系统的线下真实毛利数据预计结项达成5%。 9.19 运营审视会结论：1、关注单月盈利情况，需守住回正底线；进度填报有问题，建议项目经理弄一版线下真实的NR和成本数据 2、CADDM项目整体按计划收尾，需重点控制二期需求范围和人员成本 8.30 1、CDDM项目二期客户指定我司继续承接，一期项目人员到二期继续投入，9月淘汰置换1人 2、需求管理系统项目8月的成本对比7月已经减少2w
A14: 泛AIoT与设备商事业部 | B14: 理想汽车-2024-2026年罗克维尔斯智能商业开发委托协议ODC-FP项目 | C14: 罗克维尔斯智能商业项目继续调优回到正常运营水平，下次会议明确回到正常运营水平的时间 | D14: 9月会议汇报当月运营情况 | E14: 45888 | F14: 侯黎明 | G14: 45910 | I14: 关闭 | J14: 10.29 9月运营损益当月已回正。 9.19 运营审视会结论：大勇总要求务必保证单月回正，建议从客户侧寻找预算调整空间。 需建立更严格的人员成本管控机制，优先保障核心业务线盈利。 项目存在持续亏损风险，需加速人员优化和业务转型
A15: 电信联通综合事业部 | B15: 农业项目群 | C15: 【农业项目群】亏损 | D15: 9月份预期会签一个200多万国产化农业项目，如该项目未签下，则对团队中高成本人员做出调整； | E15: 45919 | F15: 沙建银 | G15: 45930 | I15: 打开 | J15: 10.29 持续跟进中，尚无进展。 9.19 该项目暂无进展
A16: 电信联通综合事业部 | B16: 南京联创项目 | C16: 南京联创等6个运营填报异常 | D16: 项目10月填报修正 | E16: 45919 | F16: 沙建银 | G16: 45930 | I16: 关闭 | J16: 10.29 除南京联创外其余项目毛利已正常 9.19 9月产出填报进行纠偏

Sheet 实际运营数据-李陶
A1: 项目编码 | B1: 项目名称 | C1: 项目开始时间 | D1: 项目结束时间 | E1: 1月项目人数 | F1: 2月项目人数 | G1: 3月项目人数 | H1: 4月项目人数 | I1: 5月项目人数 | J1: 6月项目人数 | K1: 7月项目人数 | L1: 8月项目人数 | M1: 9月项目人数 | N1: 10月项目人数 | O1: 11月项目人数 | P1: 12月项目人数 | Q1: 结算方式 | R1: 类别 | S1: 项目整体毛利目标预算 | T1: 项目开始-当前实际累计 | U1: 项目开始-25年实际累计 | V1: 26年YTD实际累计12月 | W1: 26年YTD实际累计11月 | X1: 26年YTD实际累计10月 | Y1: 26年YTD实际累计9月 | Z1: 26年YTD实际累计8月 | AA1: 26年YTD实际累计7月 | AB1: 26年YTD实际累计6月 | AC1: 26年YTD实际累计5月 | AD1: 26年YTD实际累计4月 | AE1: 26年YTD实际累计3月 | AF1: 26年YTD实际累计2月 | AG1: 26年YTD实际累计1月 | AH1: 项目周期偏差 （实际-预估） | AI1: YTD当年偏差 （实际-预估） | AJ1: 项目周期偏差原因分析 （截止25年底毛利偏差原因） | AK1: YTD当年偏差原因分析 | AL1: 改进措施 | AM1: 进展 | AN1: 真实经营数据 | AO1: 202612 | AP1: 202611 | AQ1: 202610 | AR1: 202609 | AS1: 202608 | AT1: 202607 | AU1: 202606 | AV1: 202605 | AW1: 202604 | AX1: 202603 | AY1: 202602 | AZ1: 202601 | BA1: 2025年 | BB1: 2024年 | BC1: 2023年 | BD1: 备注
A2: P202502000351 | B2: 用友-2025年铁塔视联平台开发外包项目-FP项目 | C2: 45689 | D2: 46054 | E2: 无投入 | F2: 无投入 | Q2: 工作量结算 | R2: 累计收入（NR） | S2: 3773584.9 | T2: =SUM(AO2:BC2) -> 1123771.4 | U2: =SUM(BA2:BC2) -> 1123771.4 | V2: =SUM(AO2:AZ2) -> 0 | W2: =SUM(AP2:AZ2) -> 0 | X2: =SUM(AQ2:AZ2) -> 0 | Y2: =SUM(AR2:AZ2) -> 0 | Z2: =SUM(AS2:AZ2) -> 0 | AA2: =SUM(AT2:AZ2) -> 0 | AB2: =SUM(AU2:AZ2) -> 0 | AC2: =SUM(AV2:AZ2) -> 0 | AD2: =SUM(AW2:AZ2) -> 0 | AE2: =SUM(AX2:AZ2) -> 0 | AF2: =SUM(AY2:AZ2) -> 0 | AG2: =SUM(AZ2:AZ2) -> 0 | AJ2: 1、因25年铁塔未中标，涉及提前投入的280万产出，回冲 2、项目25年7月结束，之后都是闲置成本挂在项目上 | AK2: 1人的闲置/释放成本挂在项目上，持续拉低项目毛利 | AL2: 项目已结束，该部分产出已确认追不回 | AM2: / | AY2: 0 | AZ2: 0 | BA2: 1123771.4
R3: 人工成本（成本１） | S3: 3399851.2 | T3: =SUM(AO3:BC3) -> 3360415.5 | U3: =SUM(BA3:BC3) -> 3296069.5 | V3: =SUM(AO3:AZ3) -> 64346 | W3: =SUM(AP3:AZ3) -> 64346 | X3: =SUM(AQ3:AZ3) -> 64346 | Y3: =SUM(AR3:AZ3) -> 64346 | Z3: =SUM(AS3:AZ3) -> 64346 | AA3: =SUM(AT3:AZ3) -> 64346 | AB3: =SUM(AU3:AZ3) -> 64346 | AC3: =SUM(AV3:AZ3) -> 64346 | AD3: =SUM(AW3:AZ3) -> 64346 | AE3: =SUM(AX3:AZ3) -> 64346 | AF3: =SUM(AY3:AZ3) -> 64346 | AG3: =SUM(AZ3:AZ3) -> 64346 | AY3: 0 | AZ3: 64346 | BA3: 3296069.5
R4: 闲置成本（成本2） | AY4: -17.28
R5: 差旅费（成本３） | S5: 30000 | T5: =SUM(AO5:BC5) -> 0 | U5: =SUM(BA5:BC5) -> 0 | V5: =SUM(AO5:AZ5) -> 0 | W5: =SUM(AP5:AZ5) -> 0 | X5: =SUM(AQ5:AZ5) -> 0 | Y5: =SUM(AR5:AZ5) -> 0 | Z5: =SUM(AS5:AZ5) -> 0 | AA5: =SUM(AT5:AZ5) -> 0 | AB5: =SUM(AU5:AZ5) -> 0 | AC5: =SUM(AV5:AZ5) -> 0 | AD5: =SUM(AW5:AZ5) -> 0 | AE5: =SUM(AX5:AZ5) -> 0 | AF5: =SUM(AY5:AZ5) -> 0 | AG5: =SUM(AZ5:AZ5) -> 0 | AY5: 0 | AZ5: 0 | BA5: 0
R6: 其他成本（成本３） | S6: 0 | T6: =SUM(AO6:BC6) -> 51415.11 | U6: =SUM(BA6:BC6) -> 50651.07 | V6: =SUM(AO6:AZ6) -> 764.04 | W6: =SUM(AP6:AZ6) -> 764.04 | X6: =SUM(AQ6:AZ6) -> 764.04 | Y6: =SUM(AR6:AZ6) -> 764.04 | Z6: =SUM(AS6:AZ6) -> 764.04 | AA6: =SUM(AT6:AZ6) -> 764.04 | AB6: =SUM(AU6:AZ6) -> 764.04 | AC6: =SUM(AV6:AZ6) -> 764.04 | AD6: =SUM(AW6:AZ6) -> 764.04 | AE6: =SUM(AX6:AZ6) -> 764.04 | AF6: =SUM(AY6:AZ6) -> 764.04 | AG6: =SUM(AZ6:AZ6) -> 382.02 | AY6: 382.02 | AZ6: 382.02 | BA6: 50651.07
R7: 累计成本 | S7: =SUM(S3:S6) -> 3429851.2 | T7: =SUM(T3:T6) -> 3411830.6 | U7: =SUM(U3:U6) -> 3346720.5 | V7: =SUM(V3:V6) -> 65110.04 | W7: =SUM(W3:W6) -> 65110.04 | X7: =SUM(X3:X6) -> 65110.04 | Y7: =SUM(Y3:Y6) -> 65110.04 | Z7: =SUM(Z3:Z6) -> 65110.04 | ... AI7: =SUM(AI3:AI6) -> 0 | AO7: =SUM(AO3:AO6) -> 0 | AP7: =SUM(AP3:AP6) -> 0 | AQ7: =SUM(AQ3:AQ6) -> 0 | AR7: =SUM(AR3:AR6) -> 0 | AS7: =SUM(AS3:AS6) -> 0 | AT7: =SUM(AT3:AT6) -> 0 | AU7: =SUM(AU3:AU6) -> 0 | AV7: =SUM(AV3:AV6) -> 0 | ... BA7: =SUM(BA3:BA6) -> 3346720.5
R8: GP1毛利 | S8: =S2-S3 -> 373733.68 | T8: =T2-T3 -> -2236644.1 | U8: =U2-U3 -> -2172298.1 | V8: =V2-V3 -> -64346 | W8: =W2-W3 -> -64346 | X8: =X2-X3 -> -64346 | Y8: =Y2-Y3 -> -64346 | Z8: =Z2-Z3 -> -64346 | ... AG8: =AG2-AG3 -> -64346 | AO8: =AO2-AO3 -> 0 | AP8: =AP2-AP3 -> 0 | AQ8: =AQ2-AQ3 -> 0 | AR8: =AR2-AR3 -> 0 | AS8: =AS2-AS3 -> 0 | AT8: =AT2-AT3 -> 0 | AU8: =AU2-AU3 -> 0 | AV8: =AV2-AV3 -> 0 | ... AZ8: =AZ2-AZ3 -> -64346 | BA8: -2110302
R9: GP1毛利率(%) | S9: =S8/S2 -> 0.099039425 | T9: =T8/T2 -> -1.9903017 | U9: =U8/U2 -> -1.9330427 | V9: =V8/V2 -> #DIV/0! | W9: =W8/W2 -> #DIV/0! | X9: =X8/X2 -> #DIV/0! | Y9: =Y8/Y2 -> #DIV/0! | Z9: =Z8/Z2 -> #DIV/0! | ... AG9: =AG8/AG2 -> #DIV/0! | AH9: =T9-S9 -> -2.0893411 | AI9: =AF9-S9 -> #DIV/0! | AO9: =AO8/AO2 -> #DIV/0! | AP9: =AP8/AP2 -> #DIV/0! | AQ9: =AQ8/AQ2 -> #DIV/0! | AR9: =AR8/AR2 -> #DIV/0! | AS9: =AS8/AS2 -> #DIV/0! | AT9: =AT8/AT2 -> #DIV/0! | AU9: =AU8/AU2 -> #DIV/0! | AV9: =AV8/AV2 -> #DIV/0! | ... AZ9: =AZ8/AZ2 -> #DIV/0! | BA9: -1.8777077
R10: GP3毛利 | S10: =S2-S3-S5-S6 -> 343733.68 | T10: =T2-T3-T5-T6 -> -2288059.2 | U10: =U2-U3-U5-U6 -> -2222949.2 | V10: =V2-V3-V5-V6 -> -65110.04 | W10: =W2-W3-W5-W6 -> -65110.04 | X10: =X2-X3-X5-X6 -> -65110.04 | Y10: =Y2-Y3-Y5-Y6 -> -65110.04 | Z10: =Z2-Z3-Z5-Z6 -> -65110.04 | ... AG10: =AG2-AG3-AG5-AG6 -> -64728.02 | AO10: =AO2-AO3-AO5-AO6 -> 0 | AP10: =AP2-AP3-AP5-AP6 -> 0 | AQ10: =AQ2-AQ3-AQ5-AQ6 -> 0 | AR10: =AR2-AR3-AR5-AR6 -> 0 | AS10: =AS2-AS3-AS5-AS6 -> 0 | AT10: =AT2-AT3-AT5-AT6 -> 0 | AU10: =AU2-AU3-AU5-AU6 -> 0 | AV10: =AV2-AV3-AV5-AV6 -> 0 | ... AZ10: =AZ2-AZ3-AZ5-AZ6 -> -64728.02 | BA10: -2162053.7
R11: GP3毛利率(%) | S11: =S10/S2 -> 0.091089425 | T11: =T10/T2 -> -2.036054 | U11: =U10/U2 -> -1.9781151 | V11: =V10/V2 -> #DIV/0! | W11: =W10/W2 -> #DIV/0! | X11: =X10/X2 -> #DIV/0! | Y11: =Y10/Y2 -> #DIV/0! | Z11: =Z10/Z2 -> #DIV/0! | ... AG11: =AG10/AG2 -> #DIV/0! | AH11: =T11-S11 -> -2.1271434 | AI11: =AF11-S11 -> #DIV/0! | AO11: =AO10/AO2 -> #DIV/0! | AP11: =AP10/AP2 -> #DIV/0! | AQ11: =AQ10/AQ2 -> #DIV/0! | AR11: =AR10/AR2 -> #DIV/0! | AS11: =AS10/AS2 -> #DIV/0! | AT11: =AT10/AT2 -> #DIV/0! | AU11: =AU10/AU2 -> #DIV/0! | AV11: =AV10/AV2 -> #DIV/0! | ... AZ11: =AZ10/AZ2 -> #DIV/0! | BA11: -1.9237555
A12: P202501000688 | B12: 长安汽车-2025年企业数字化需求管理系统项目技术服务合同-FP项目 | C12: 45658 | D12: 46022 | E12: 无投入 | F12: 无投入 | Q12: 总价进度结算 | R12: 累计收入（NR） | S12: 773774.3 | T12: =SUM(AO12:BC12) -> 748845.73 | U12: =SUM(BA12:BC12) -> 748845.73 | V12: =SUM(AO12:AZ12) -> 0 | W12: =SUM(AP12:AZ12) -> 0 | X12: =SUM(AQ12:AZ12) -> 0 | Y12: =SUM(AR12:AZ12) -> 0 | Z12: =SUM(AS12:AZ12) -> 0 | AA12: =SUM(AT12:AZ12) -> 0 | AB12: =SUM(AU12:AZ12) -> 0 | AC12: =SUM(AV12:AZ12) -> 0 | AD12: =SUM(AW12:AZ12) -> 0 | AE12: =SUM(AX12:AZ12) -> 0 | AF12: =SUM(AY12:AZ12) -> 0 | AG12: =SUM(AZ12:AZ12) -> 0 | AJ12: / | AK12: 1、长安大数据中心重点项目，咨询+实施+产品运营项目，前期需求调研阶段，客户要求投入流程体系顾问、产品顾问、敏捷专家、 产品经理等高成本人员多，且异地出差费用高，导致成本超预算。6月 7月进入研发测试周期，临时借调人员集中投入导致毛利进一步拉低。 2、项目产出上报偏差问题，当前总体进展70%，项目总金额82W，累计成本49.8W，根据进度实际应上报NR57.4W，项目毛利11.5%，基本达标。 | AL12: 预计7月底释放1个顾问，1个UI、3个研发测试人员，8月底释放1个产品顾问，缩减成本 | AM12: 结项负毛利。 | AN12: 除项目经理外，人员与长安TM、理想项目复用 | AY12: 0 | AZ12: 0 | BA12: 748845.73
R13: 人工成本（成本１） | S13: 681148.69 | T13: =SUM(AO13:BC13) -> 786458.31 | U13: =SUM(BA13:BC13) -> 786258.31 | V13: =SUM(AO13:AZ13) -> 200 | W13: =SUM(AP13:AZ13) -> 200 | X13: =SUM(AQ13:AZ13) -> 200 | Y13: =SUM(AR13:AZ13) -> 200 | Z13: =SUM(AS13:AZ13) -> 200 | AA13: =SUM(AT13:AZ13) -> 200 | AB13: =SUM(AU13:AZ13) -> 200 | AC13: =SUM(AV13:AZ13) -> 200 | AD13: =SUM(AW13:AZ13) -> 200 | AE13: =SUM(AX13:AZ13) -> 200 | AF13: =SUM(AY13:AZ13) -> 200 | AG13: =SUM(AZ13:AZ13) -> 200 | AY13: 0 | AZ13: 200 | BA13: 786258.31
R14: 差旅费（成本３） | S14: 0 | T14: =SUM(AO14:BC14) -> 37279.88 | U14: =SUM(BA14:BC14) -> 37279.88 | V14: =SUM(AO14:AZ14) -> 0 | W14: =SUM(AP14:AZ14) -> 0 | X14: =SUM(AQ14:AZ14) -> 0 | Y14: =SUM(AR14:AZ14) -> 0 | Z14: =SUM(AS14:AZ14) -> 0 | AA14: =SUM(AT14:AZ14) -> 0 | AB14: =SUM(AU14:AZ14) -> 0 | AC14: =SUM(AV14:AZ14) -> 0 | AD14: =SUM(AW14:AZ14) -> 0 | AE14: =SUM(AX14:AZ14) -> 0 | AF14: =SUM(AY14:AZ14) -> 0 | AG14: =SUM(AZ14:AZ14) -> 0 | AY14: 0 | AZ14: 0 | BA14: 37279.88
R15: 其他成本（成本３） | S15: 0 | T15: =SUM(AO15:BC15) -> 4713.69 | U15: =SUM(BA15:BC15) -> 4014.49 | V15: =SUM(AO15:AZ15) -> 699.2 | W15: =SUM(AP15:AZ15) -> 699.2 | X15: =SUM(AQ15:AZ15) -> 699.2 | Y15: =SUM(AR15:AZ15) -> 699.2 | Z15: =SUM(AS15:AZ15) -> 699.2 | AA15: =SUM(AT15:AZ15) -> 699.2 | AB15: =SUM(AU15:AZ15) -> 699.2 | AC15: =SUM(AV15:AZ15) -> 699.2 | AD15: =SUM(AW15:AZ15) -> 699.2 | AE15: =SUM(AX15:AZ15) -> 699.2 | AF15: =SUM(AY15:AZ15) -> 699.2 | AG15: =SUM(AZ15:AZ15) -> 349.6 | AY15: 349.6 | AZ15: 349.6 | BA15: 4014.49
R16: 累计成本 | S16: =SUM(S13:S15) -> 681148.69 | T16: =SUM(T13:T15) -> 828451.88 | U16: =SUM(U13:U15) -> 827552.68 | V16: =SUM(V13:V15) -> 899.2 | W16: =SUM(W13:W15) -> 899.2 | X16: =SUM(X13:X15) -> 899.2 | Y16: =SUM(Y13:Y15) -> 899.2 | Z16: =SUM(Z13:Z15) -> 899.2 | ... AI16: =SUM(AI13:AI15) -> 0 | AO16: =SUM(AO13:AO15) -> 0 | AP16: =SUM(AP13:AP15) -> 0 | AQ16: =SUM(AQ13:AQ15) -> 0 | AR16: =SUM(AR13:AR15) -> 0 | AS16: =SUM(AS13:AS15) -> 0 | AT16: =SUM(AT13:AT15) -> 0 | AU16: =SUM(AU13:AU15) -> 0 | AV16: =SUM(AV13:AV15) -> 0 | ... BA16: =SUM(BA13:BA15) -> 827552.68
R17: GP1毛利 | S17: =S12-S13 -> 92625.61 | T17: =T12-T13 -> -37612.58 | U17: =U12-U13 -> -37412.58 | V17: =V12-V13 -> -200 | W17: =W12-W13 -> -200 | X17: =X12-X13 -> -200 | Y17: =Y12-Y13 -> -200 | Z17: =Z12-Z13 -> -200 | ... AG17: =AG12-AG13 -> -200 | AO17: =AO12-AO13 -> 0 | AP17: =AP12-AP13 -> 0 | AQ17: =AQ12-AQ13 -> 0 | AR17: =AR12-AR13 -> 0 | AS17: =AS12-AS13 -> 0 | AT17: =AT12-AT13 -> 0 | AU17: =AU12-AU13 -> 0 | AV17: =AV12-AV13 -> 0 | ... AZ17: =AZ12-AZ13 -> -200 | BA17: -37412.58
R18: GP1毛利率(%) | S18: =S17/S12 -> 0.11970624 | T18: =T17/T12 -> -0.050227408 | U18: =U17/U12 -> -0.04996033 | V18: =V17/V12 -> #DIV/0! | W18: =W17/W12 -> #DIV/0! | X18: =X17/X12 -> #DIV/0! | Y18: =Y17/Y12 -> #DIV/0! | Z18: =Z17/Z12 -> #DIV/0! | ... AG18: =AG17/AG12 -> #DIV/0! | AH18: =T18-S18 -> -0.16993365 | AI18: =AF18-S18 -> #DIV/0! | AO18: =AO17/AO12 -> #DIV/0! | AP18: =AP17/AP12 -> #DIV/0! | AQ18: =AQ17/AQ12 -> #DIV/0! | AR18: =AR17/AR12 -> #DIV/0! | AS18: =AS17/AS12 -> #DIV/0! | AT18: =AT17/AT12 -> #DIV/0! | AU18: =AU17/AU12 -> #DIV/0! | AV18: =AV17/AV12 -> #DIV/0! | ... AZ18: =AZ17/AZ12 -> #DIV/0! | BA18: -0.04996033
R19: GP3毛利 | S19: =S12-S13-S14-S15 -> 92625.61 | T19: =T12-T13-T14-T15 -> -79606.15 | U19: =U12-U13-U14-U15 -> -78706.95 | V19: =V12-V13-V14-V15 -> -899.2 | W19: =W12-W13-W14-W15 -> -899.2 | X19: =X12-X13-X14-X15 -> -899.2 | Y19: =Y12-Y13-Y14-Y15 -> -899.2 | Z19: =Z12-Z13-Z14-Z15 -> -899.2 | ... AG19: =AG12-AG13-AG14-AG15 -> -549.6 | AO19: =AO12-AO13-AO14-AO15 -> 0 | AP19: =AP12-AP13-AP14-AP15 -> 0 | AQ19: =AQ12-AQ13-AQ14-AQ15 -> 0 | AR19: =AR12-AR13-AR14-AR15 -> 0 | AS19: =AS12-AS13-AS14-AS15 -> 0 | AT19: =AT12-AT13-AT14-AT15 -> 0 | AU19: =AU12-AU13-AU14-AU15 -> 0 | AV19: =AV12-AV13-AV14-AV15 -> 0 | ... AZ19: =AZ12-AZ13-AZ14-AZ15 -> -549.6 | BA19: -78706.95
R20: GP3毛利率(%) | S20: =S19/S12 -> 0.11970624 | T20: =T19/T12 -> -0.10630514 | U20: =U19/U12 -> -0.10510436 | V20: =V19/V12 -> #DIV/0! | W20: =W19/W12 -> #DIV/0! | X20: =X19/X12 -> #DIV/0! | Y20: =Y19/Y12 -> #DIV/0! | Z20: =Z19/Z12 -> #DIV/0! | ... AG20: =AG19/AG12 -> #DIV/0! | AH20: =T20-S20 -> -0.22601138 | AI20: =AF20-S20 -> #DIV/0! | AO20: =AO19/AO12 -> #DIV/0! | AP20: =AP19/AP12 -> #DIV/0! | AQ20: =AQ19/AQ12 -> #DIV/0! | AR20: =AR19/AR12 -> #DIV/0! | AS20: =AS19/AS12 -> #DIV/0! | AT20: =AT19/AT12 -> #DIV/0! | AU20: =AU19/AU12 -> #DIV/0! | AV20: =AV19/AV12 -> #DIV/0! | ... AZ20: =AZ19/AZ12 -> #DIV/0! | BA20: -0.10510436
A21: P202505000063 | B21: 天府再生资源-2025-2027年云平台建设服务合同-FP项目 | C21: 45774 | D21: 46387 | E21: 项目实际人数：21人 人力成本表人数：21人，合计17人月 | F21: 项目实际人数：14人 人力成本表人数：14人，合计12.5人月 | Q21: 总价进度结算 | R21: 累计收入（NR） | S21: 2641509.4 | T21: =SUM(AO21:BC21) -> 1572990.3 | U21: =SUM(BA21:BC21) -> 1048660.2 | V21: =SUM(AO21:AZ21) -> 524330.13 | W21: =SUM(AP21:AZ21) -> 524330.13 | X21: =SUM(AQ21:AZ21) -> 524330.13 | Y21: =SUM(AR21:AZ21) -> 524330.13 | Z21: =SUM(AS21:AZ21) -> 524330.13 | AA21: =SUM(AT21:AZ21) -> 524330.13 | AB21: =SUM(AU21:AZ21) -> 524330.13 | AC21: =SUM(AV21:AZ21) -> 524330.13 | AD21: =SUM(AW21:AZ21) -> 524330.13 | AE21: =SUM(AX21:AZ21) -> 524330.13 | AF21: =SUM(AY21:AZ21) -> 524330.13 | AG21: =SUM(AZ21:AZ21) -> 194002.16 | AJ21: / | AK21: 10月交付进度填报偏差大，导致10月的产出多报，在11月进行纠偏回调 | AL21: 实际投入与预算尽量贴合，保证产出稳定 | AM21: 3/12 2月交付进度已追回，当月毛利回正 | AY21: 330327.97 | AZ21: 194002.16 | BA21: 1048660.2
R22: 人工成本（成本１） | S22: 2234139 | T22: =SUM(AO22:BC22) -> 1338773.8 | U22: =SUM(BA22:BC22) -> 956409.4 | V22: =SUM(AO22:AZ22) -> 382364.35 | W22: =SUM(AP22:AZ22) -> 382364.35 | X22: =SUM(AQ22:AZ22) -> 382364.35 | Y22: =SUM(AR22:AZ22) -> 382364.35 | Z22: =SUM(AS22:AZ22) -> 382364.35 | AA22: =SUM(AT22:AZ22) -> 382364.35 | AB22: =SUM(AU22:AZ22) -> 382364.35 | AC22: =SUM(AV22:AZ22) -> 382364.35 | AD22: =SUM(AW22:AZ22) -> 382364.35 | AE22: =SUM(AX22:AZ22) -> 382364.35 | AF22: =SUM(AY22:AZ22) -> 382364.35 | AG22: =SUM(AZ22:AZ22) -> 199405.64 | AY22: 182958.71 | AZ22: 199405.64 | BA22: 956409.4
R23: 差旅费（成本３） | S23: 0 | T23: =SUM(AO23:BC23) -> 0 | U23: =SUM(BA23:BC23) -> 0 | V23: =SUM(AO23:AZ23) -> 0 | W23: =SUM(AP23:AZ23) -> 0 | X23: =SUM(AQ23:AZ23) -> 0 | Y23: =SUM(AR23:AZ23) -> 0 | Z23: =SUM(AS23:AZ23) -> 0 | AA23: =SUM(AT23:AZ23) -> 0 | AB23: =SUM(AU23:AZ23) -> 0 | AC23: =SUM(AV23:AZ23) -> 0 | AD23: =SUM(AW23:AZ23) -> 0 | AE23: =SUM(AX23:AZ23) -> 0 | AF23: =SUM(AY23:AZ23) -> 0 | AG23: =SUM(AZ23:AZ23) -> 0 | AY23: 0 | AZ23: 0 | BA23: 0
R24: 其他成本（成本３） | S24: 0 | T24: =SUM(AO24:BC24) -> 4022 | U24: =SUM(BA24:BC24) -> 2454.8 | V24: =SUM(AO24:AZ24) -> 1567.2 | W24: =SUM(AP24:AZ24) -> 1567.2 | X24: =SUM(AQ24:AZ24) -> 1567.2 | Y24: =SUM(AR24:AZ24) -> 1567.2 | Z24: =SUM(AS24:AZ24) -> 1567.2 | AA24: =SUM(AT24:AZ24) -> 1567.2 | AB24: =SUM(AU24:AZ24) -> 1567.2 | AC24: =SUM(AV24:AZ24) -> 1567.2 | AD24: =SUM(AW24:AZ24) -> 1567.2 | AE24: =SUM(AX24:AZ24) -> 1567.2 | AF24: =SUM(AY24:AZ24) -> 1567.2 | AG24: =SUM(AZ24:AZ24) -> 787.2 | AY24: 780 | AZ24: 787.2 | BA24: 2454.8
R25: 累计成本 | S25: =SUM(S22:S24) -> 2234139 | T25: =SUM(T22:T24) -> 1342795.8 | U25: =SUM(U22:U24) -> 958864.2 | V25: =SUM(V22:V24) -> 383931.55 | W25: =SUM(W22:W24) -> 383931.55 | X25: =SUM(X22:X24) -> 383931.55 | Y25: =SUM(Y22:Y24) -> 383931.55 | Z25: =SUM(Z22:Z24) -> 383931.55 | ... AI25: =SUM(AI22:AI24) -> 0 | AO25: =SUM(AO22:AO24) -> 0 | AP25: =SUM(AP22:AP24) -> 0 | AQ25: =SUM(AQ22:AQ24) -> 0 | AR25: =SUM(AR22:AR24) -> 0 | AS25: =SUM(AS22:AS24) -> 0 | AT25: =SUM(AT22:AT24) -> 0 | AU25: =SUM(AU22:AU24) -> 0 | AV25: =SUM(AV22:AV24) -> 0 | ... BA25: =SUM(BA22:BA24) -> 958864.2
R26: GP1毛利 | S26: =S21-S22 -> 407370.41 | T26: =T21-T22 -> 234216.59 | U26: =U21-U22 -> 92250.81 | V26: =V21-V22 -> 141965.78 | W26: =W21-W22 -> 141965.78 | X26: =X21-X22 -> 141965.78 | Y26: =Y21-Y22 -> 141965.78 | Z26: =Z21-Z22 -> 141965.78 | ... AG26: =AG21-AG22 -> -5403.48 | AO26: =AO21-AO22 -> 0 | AP26: =AP21-AP22 -> 0 | AQ26: =AQ21-AQ22 -> 0 | AR26: =AR21-AR22 -> 0 | AS26: =AS21-AS22 -> 0 | AT26: =AT21-AT22 -> 0 | AU26: =AU21-AU22 -> 0 | AV26: =AV21-AV22 -> 0 | ... AZ26: =AZ21-AZ22 -> -5403.48 | BA26: 92250.81
R27: GP1毛利率(%) | S27: =S26/S21 -> 0.1542188 | T27: =T26/T21 -> 0.14889894 | U27: =U26/U21 -> 0.087970163 | V27: =V26/V21 -> 0.27075648 | W27: =W26/W21 -> 0.27075648 | X27: =X26/X21 -> 0.27075648 | Y27: =Y26/Y21 -> 0.27075648 | Z27: =Z26/Z21 -> 0.27075648 | ... AG27: =AG26/AG21 -> -0.02785268 | AH27: =T27-S27 -> -0.005319861 | AI27: =AF27-S27 -> 0.11653768 | AO27: =AO26/AO21 -> #DIV/0! | AP27: =AP26/AP21 -> #DIV/0! | AQ27: =AQ26/AQ21 -> #DIV/0! | AR27: =AR26/AR21 -> #DIV/0! | AS27: =AS26/AS21 -> #DIV/0! | AT27: =AT26/AT21 -> #DIV/0! | AU27: =AU26/AU21 -> #DIV/0! | AV27: =AV26/AV21 -> #DIV/0! | ... AZ27: =AZ26/AZ21 -> -0.02785268 | BA27: 0.087970163
R28: GP3毛利 | S28: =S21-S22-S23-S24 -> 407370.41 | T28: =T21-T22-T23-T24 -> 230194.59 | U28: =U21-U22-U23-U24 -> 89796.01 | V28: =V21-V22-V23-V24 -> 140398.58 | W28: =W21-W22-W23-W24 -> 140398.58 | X28: =X21-X22-X23-X24 -> 140398.58 | Y28: =Y21-Y22-Y23-Y24 -> 140398.58 | Z28: =Z21-Z22-Z23-Z24 -> 140398.58 | ... AG28: =AG21-AG22-AG23-AG24 -> -6190.68 | AO28: =AO21-AO22-AO23-AO24 -> 0 | AP28: =AP21-AP22-AP23-AP24 -> 0 | AQ28: =AQ21-AQ22-AQ23-AQ24 -> 0 | AR28: =AR21-AR22-AR23-AR24 -> 0 | AS28: =AS21-AS22-AS23-AS24 -> 0 | AT28: =AT21-AT22-AT23-AT24 -> 0 | AU28: =AU21-AU22-AU23-AU24 -> 0 | AV28: =AV21-AV22-AV23-AV24 -> 0 | ... AZ28: =AZ21-AZ22-AZ23-AZ24 -> -6190.68 | BA28: 89796.01
R29: GP3毛利率(%) | S29: =S28/S21 -> 0.1542188 | T29: =T28/T21 -> 0.14634202 | U29: =U28/U21 -> 0.085629272 | V29: =V28/V21 -> 0.26776752 | W29: =W28/W21 -> 0.26776752 | X29: =X28/X21 -> 0.26776752 | Y29: =Y28/Y21 -> 0.26776752 | Z29: =Z28/Z21 -> 0.26776752 | ... AG29: =AG28/AG21 -> -0.031910366 | AH29: =T29-S29 -> -0.0078767744 | AI29: =AF29-S29 -> 0.11354872 | AO29: =AO28/AO21 -> #DIV/0! | AP29: =AP28/AP21 -> #DIV/0! | AQ29: =AQ28/AQ21 -> #DIV/0! | AR29: =AR28/AR21 -> #DIV/0! | AS29: =AS28/AS21 -> #DIV/0! | AT29: =AT28/AT21 -> #DIV/0! | AU29: =AU28/AU21 -> #DIV/0! | AV29: =AV28/AV21 -> #DIV/0! | ... AZ29: =AZ28/AZ21 -> -0.031910366 | BA29: 0.085629272
A30: P202507000256 | B30: 常熟酒业-碰碰杯地域性SaaS系统开发项目-FP | C30: 45852 | D30: 46081 | E30: 项目实际人数：14人 人力成本表人数：14人，合计12.67人月 | F30: 项目实际人数：4人 人力成本表人数：4人，合计4人月 | Q30: 总价进度结算 | R30: 累计收入（NR） | S30: 1171698.1 | T30: =SUM(AO30:BC30) -> 1162988.8 | U30: =SUM(BA30:BC30) -> 987292.99 | V30: =SUM(AO30:AZ30) -> 175695.83 | W30: =SUM(AP30:AZ30) -> 175695.83 | X30: =SUM(AQ30:AZ30) -> 175695.83 | Y30: =SUM(AR30:AZ30) -> 175695.83 | Z30: =SUM(AS30:AZ30) -> 175695.83 | AA30: =SUM(AT30:AZ30) -> 175695.83 | AB30: =SUM(AU30:AZ30) -> 175695.83 | AC30: =SUM(AV30:AZ30) -> 175695.83 | AD30: =SUM(AW30:AZ30) -> 175695.83 | AE30: =SUM(AX30:AZ30) -> 175695.83 | AF30: =SUM(AY30:AZ30) -> 175695.83 | AG30: =SUM(AZ30:AZ30) -> 112915.39 | AJ30: / | AK30: 3/13 25年的差旅成本去年没让报，集中在项目结项最后一个月产生大量的差旅和报销成本 | AM30: 3/13 项目结项，在推动客户验收和洽谈下一期。当前整体毛利在6个点，低于预算。 | AY30: 62780.44 | AZ30: 112915.39 | BA30: 987292.99
R31: 人工成本（成本１） | S31: 866909.85 | T31: =SUM(AO31:BC31) -> 1013204.6 | U31: =SUM(BA31:BC31) -> 775244.31 | V31: =SUM(AO31:AZ31) -> 237960.26 | W31: =SUM(AP31:AZ31) -> 237960.26 | X31: =SUM(AQ31:AZ31) -> 237960.26 | Y31: =SUM(AR31:AZ31) -> 237960.26 | Z31: =SUM(AS31:AZ31) -> 237960.26 | AA31: =SUM(AT31:AZ31) -> 237960.26 | AB31: =SUM(AU31:AZ31) -> 237960.26 | AC31: =SUM(AV31:AZ31) -> 237960.26 | AD31: =SUM(AW31:AZ31) -> 237960.26 | AE31: =SUM(AX31:AZ31) -> 237960.26 | AF31: =SUM(AY31:AZ31) -> 237960.26 | AG31: =SUM(AZ31:AZ31) -> 183731.89 | AY31: 54228.37 | AZ31: 183731.89 | BA31: 775244.31
R32: 差旅费（成本３） | S32: 40000 | T32: =SUM(AO32:BC32) -> 71094.51 | U32: =SUM(BA32:BC32) -> 0 | V32: =SUM(AO32:AZ32) -> 71094.51 | W32: =SUM(AP32:AZ32) -> 71094.51 | X32: =SUM(AQ32:AZ32) -> 71094.51 | Y32: =SUM(AR32:AZ32) -> 71094.51 | Z32: =SUM(AS32:AZ32) -> 71094.51 | AA32: =SUM(AT32:AZ32) -> 71094.51 | AB32: =SUM(AU32:AZ32) -> 71094.51 | AC32: =SUM(AV32:AZ32) -> 71094.51 | AD32: =SUM(AW32:AZ32) -> 71094.51 | AE32: =SUM(AX32:AZ32) -> 71094.51 | AF32: =SUM(AY32:AZ32) -> 71094.51 | AG32: =SUM(AZ32:AZ32) -> 0 | AY32: 71094.51 | AZ32: 0 | BA32: 0
R33: 其他成本（成本３） | S33: 30000 | T33: =SUM(AO33:BC33) -> 5555.18 | U33: =SUM(BA33:BC33) -> 1283.33 | V33: =SUM(AO33:AZ33) -> 4271.85 | W33: =SUM(AP33:AZ33) -> 4271.85 | X33: =SUM(AQ33:AZ33) -> 4271.85 | Y33: =SUM(AR33:AZ33) -> 4271.85 | Z33: =SUM(AS33:AZ33) -> 4271.85 | AA33: =SUM(AT33:AZ33) -> 4271.85 | AB33: =SUM(AU33:AZ33) -> 4271.85 | AC33: =SUM(AV33:AZ33) -> 4271.85 | AD33: =SUM(AW33:AZ33) -> 4271.85 | AE33: =SUM(AX33:AZ33) -> 4271.85 | AF33: =SUM(AY33:AZ33) -> 4271.85 | AG33: =SUM(AZ33:AZ33) -> 802.45 | AY33: 3469.4 | AZ33: 802.45 | BA33: 1283.33
R34: 累计成本 | S34: =SUM(S31:S33) -> 936909.85 | T34: =SUM(T31:T33) -> 1089854.3 | U34: =SUM(U31:U33) -> 776527.64 | V34: =SUM(V31:V33) -> 313326.62 | W34: =SUM(W31:W33) -> 313326.62 | X34: =SUM(X31:X33) -> 313326.62 | Y34: =SUM(Y31:Y33) -> 313326.62 | Z34: =SUM(Z31:Z33) -> 313326.62 | ... AI34: =SUM(AI31:AI33) -> 0 | AO34: =SUM(AO31:AO33) -> 0 | AP34: =SUM(AP31:AP33) -> 0 | AQ34: =SUM(AQ31:AQ33) -> 0 | AR34: =SUM(AR31:AR33) -> 0 | AS34: =SUM(AS31:AS33) -> 0 | AT34: =SUM(AT31:AT33) -> 0 | AU34: =SUM(AU31:AU33) -> 0 | AV34: =SUM(AV31:AV33) -> 0 | ... BA34: =SUM(BA31:BA33) -> 776527.64
R35: GP1毛利 | S35: =S30-S31 -> 304788.26 | T35: =T30-T31 -> 149784.25 | U35: =U30-U31 -> 212048.68 | V35: =V30-V31 -> -62264.43 | W35: =W30-W31 -> -62264.43 | X35: =X30-X31 -> -62264.43 | Y35: =Y30-Y31 -> -62264.43 | Z35: =Z30-Z31 -> -62264.43 | ... AG35: =AG30-AG31 -> -70816.5 | AO35: =AO30-AO31 -> 0 | AP35: =AP30-AP31 -> 0 | AQ35: =AQ30-AQ31 -> 0 | AR35: =AR30-AR31 -> 0 | AS35: =AS30-AS31 -> 0 | AT35: =AT30-AT31 -> 0 | AU35: =AU30-AU31 -> 0 | AV35: =AV30-AV31 -> 0 | ... AZ35: =AZ30-AZ31 -> -70816.5 | BA35: 212048.68
R36: GP1毛利率(%) | S36: =S35/S30 -> 0.26012525 | T36: =T35/T30 -> 0.12879251 | U36: =U35/U30 -> 0.21477786 | V36: =V35/V30 -> -0.35438764 | W36: =W35/W30 -> -0.35438764 | X36: =X35/X30 -> -0.35438764 | Y36: =Y35/Y30 -> -0.35438764 | Z36: =Z35/Z30 -> -0.35438764 | ... AG36: =AG35/AG30 -> -0.62716429 | AH36: =T36-S36 -> -0.13133274 | AI36: =AF36-S36 -> -0.61451288 | AO36: =AO35/AO30 -> #DIV/0! | AP36: =AP35/AP30 -> #DIV/0! | AQ36: =AQ35/AQ30 -> #DIV/0! | AR36: =AR35/AR30 -> #DIV/0! | AS36: =AS35/AS30 -> #DIV/0! | AT36: =AT35/AT30 -> #DIV/0! | AU36: =AU35/AU30 -> #DIV/0! | AV36: =AV35/AV30 -> #DIV/0! | ... AZ36: =AZ35/AZ30 -> -0.62716429 | BA36: 0.21477786
R37: GP3毛利 | S37: =S30-S31-S32-S33 -> 234788.26 | T37: =T30-T31-T32-T33 -> 73134.56 | U37: =U30-U31-U32-U33 -> 210765.35 | V37: =V30-V31-V32-V33 -> -137630.79 | W37: =W30-W31-W32-W33 -> -137630.79 | X37: =X30-X31-X32-X33 -> -137630.79 | Y37: =Y30-Y31-Y32-Y33 -> -137630.79 | Z37: =Z30-Z31-Z32-Z33 -> -137630.79 | ... AG37: =AG30-AG31-AG32-AG33 -> -71618.95 | AO37: =AO30-AO31-AO32-AO33 -> 0 | AP37: =AP30-AP31-AP32-AP33 -> 0 | AQ37: =AQ30-AQ31-AQ32-AQ33 -> 0 | AR37: =AR30-AR31-AR32-AR33 -> 0 | AS37: =AS30-AS31-AS32-AS33 -> 0 | AT37: =AT30-AT31-AT32-AT33 -> 0 | AU37: =AU30-AU31-AU32-AU33 -> 0 | AV37: =AV30-AV31-AV32-AV33 -> 0 | ... AZ37: =AZ30-AZ31-AZ32-AZ33 -> -71618.95 | BA37: 210765.35
R38: GP3毛利率(%) | S38: =S37/S30 -> 0.2003829 | T38: =T37/T30 -> 0.062885007 | U38: =U37/U30 -> 0.21347802 | V38: =V37/V30 -> -0.78334694 | W38: =W37/W30 -> -0.78334694 | X38: =X37/X30 -> -0.78334694 | Y38: =Y37/Y30 -> -0.78334694 | Z38: =Z37/Z30 -> -0.78334694 | ... AG38: =AG37/AG30 -> -0.63427094 | AH38: =T38-S38 -> -0.13749789 | AI38: =AF38-S38 -> -0.98372983 | AO38: =AO37/AO30 -> #DIV/0! | AP38: =AP37/AP30 -> #DIV/0! | AQ38: =AQ37/AQ30 -> #DIV/0! | AR38: =AR37/AR30 -> #DIV/0! | AS38: =AS37/AS30 -> #DIV/0! | AT38: =AT37/AT30 -> #DIV/0! | AU38: =AU37/AU30 -> #DIV/0! | AV38: =AV37/AV30 -> #DIV/0! | ... AZ38: =AZ37/AZ30 -> -0.63427094 | BA38: 0.21347802
A39: P202408001430 | B39: 中国电信河北分公司-2024-2026年翼支付平台维保项目技术服务合同-维保FP项目 | C39: 45536 | D39: 46203 | E39: 无投入 | F39: 无投入 | Q39: 工作量结算 | R39: 累计收入（NR） | S39: 130000 | T39: =SUM(AO39:BC39) -> 123872.89 | U39: =SUM(BA39:BC39) -> 123872.89 | V39: =SUM(AO39:AZ39) -> 0 | W39: =SUM(AP39:AZ39) -> 0 | X39: =SUM(AQ39:AZ39) -> 0 | Y39: =SUM(AR39:AZ39) -> 0 | Z39: =SUM(AS39:AZ39) -> 0 | AA39: =SUM(AT39:AZ39) -> 0 | AB39: =SUM(AU39:AZ39) -> 0 | AC39: =SUM(AV39:AZ39) -> 0 | AD39: =SUM(AW39:AZ39) -> 0 | AE39: =SUM(AX39:AZ39) -> 0 | AF39: =SUM(AY39:AZ39) -> 0 | AG39: =SUM(AZ39:AZ39) -> 0 | AY39: 0 | AZ39: 0 | BA39: 89122.92 | BB39: 34749.97
R40: 人工成本（成本１） | S40: 171231.22 | T40: =SUM(AO40:BC40) -> 55666.67 | U40: =SUM(BA40:BC40) -> 55666.67 | V40: =SUM(AO40:AZ40) -> 0 | W40: =SUM(AP40:AZ40) -> 0 | X40: =SUM(AQ40:AZ40) -> 0 | Y40: =SUM(AR40:AZ40) -> 0 | Z40: =SUM(AS40:AZ40) -> 0 | AA40: =SUM(AT40:AZ40) -> 0 | AB40: =SUM(AU40:AZ40) -> 0 | AC40: =SUM(AV40:AZ40) -> 0 | AD40: =SUM(AW40:AZ40) -> 0 | AE40: =SUM(AX40:AZ40) -> 0 | AF40: =SUM(AY40:AZ40) -> 0 | AG40: =SUM(AZ40:AZ40) -> 0 | AY40: 0 | AZ40: 0 | BA40: 27296.39 | BB40: 28370.28
...

Sheet 实际运营数据-崔哲
A1: 项目编码 | B1: 项目名称 | C1: 项目开始时间 | D1: 项目结束时间 | E1: 1月项目人数 | F1: 2月项目人数 | G1: 3月项目人数 | H1: 4月项目人数 | I1: 5月项目人数 | J1: 6月项目人数 | K1: 7月项目人数 | L1: 8月项目人数 | M1: 9月项目人数 | N1: 10月项目人数 | O1: 11月项目人数 | P1: 12月项目人数 | Q1: 结算方式 | R1: 类别 | S1: 项目整体毛利目标预算 | T1: 项目开始-当前实际累计 | U1: 项目开始-25年实际累计 | V1: 26年YTD实际累计12月 | W1: 26年YTD实际累计11月 | X1: 26年YTD实际累计10月 | Y1: 26年YTD实际累计9月 | Z1: 26年YTD实际累计8月 | AA1: 26年YTD实际累计7月 | AB1: 26年YTD实际累计6月 | AC1: 26年YTD实际累计5月 | AD1: 26年YTD实际累计4月 | AE1: 26年YTD实际累计3月 | AF1: 26年YTD实际累计2月 | AG1: 26年YTD实际累计1月 | AH1: 项目周期偏差 （实际-预估） | AI1: YTD当年偏差 （实际-预估） | AJ1: 项目周期偏差原因分析 （截止25年底毛利偏差原因） | AK1: YTD当年偏差原因分析 | AL1: 改进措施 | AM1: 进展 | AN1: 真实经营数据 | AO1: 202612 | AP1: 202611 | AQ1: 202610 | AR1: 202609 | AS1: 202608 | AT1: 202607 | AU1: 202606 | AV1: 202605 | AW1: 202604 | AX1: 202603 | AY1: 202602 | AZ1: 202601 | BA1: 2025年 | BB1: 2024年 | BC1: 2023年 | BD1: 备注
A2: P202603000336 | B2: 江苏端木-2026年OneNET一体交付服务2025年第一批-数智西塞项目(一期)-FP项目 | C2: 46082 | D2: 46295 | E2: 项目实际人数：xx人 人力成本表人数：xx人，合计xx人月 | G2: 17 | R2: 累计收入（NR） | S2: 938396.23 | T2: =SUM(AO2:BC2) -> 465670.67 | U2: =SUM(BA2:BC2) -> 0 | V2: =SUM(AO2:AZ2) -> 465670.67 | W2: =SUM(AP2:AZ2) -> 465670.67 | X2: =SUM(AQ2:AZ2) -> 465670.67 | Y2: =SUM(AR2:AZ2) -> 465670.67 | Z2: =SUM(AS2:AZ2) -> 465670.67 | AA2: =SUM(AT2:AZ2) -> 465670.67 | AB2: =SUM(AU2:AZ2) -> 465670.67 | AC2: =SUM(AV2:AZ2) -> 465670.67 | AD2: =SUM(AW2:AZ2) -> 465670.67 | AE2: =SUM(AX2:AZ2) -> 465670.67 | AF2: =SUM(AY2:AZ2) -> 0 | AG2: =SUM(AZ2:AZ2) -> 0 | AX2: 465670.67 | AY2: 0 | AZ2: 0 | BA2: 0
R3: 人工成本（成本１） | S3: 674250.83 | T3: =SUM(AO3:BC3) -> 352531.84 | U3: =SUM(BA3:BC3) -> 0 | V3: =SUM(AO3:AZ3) -> 352531.84 | W3: =SUM(AP3:AZ3) -> 352531.84 | X3: =SUM(AQ3:AZ3) -> 352531.84 | Y3: =SUM(AR3:AZ3) -> 352531.84 | Z3: =SUM(AS3:AZ3) -> 352531.84 | AA3: =SUM(AT3:AZ3) -> 352531.84 | AB3: =SUM(AU3:AZ3) -> 352531.84 | AC3: =SUM(AV3:AZ3) -> 352531.84 | AD3: =SUM(AW3:AZ3) -> 352531.84 | AE3: =SUM(AX3:AZ3) -> 352531.84 | AF3: =SUM(AY3:AZ3) -> 0 | AG3: =SUM(AZ3:AZ3) -> 0 | AX3: 352531.84 | AY3: 0 | AZ3: 0 | BA3: 0
R4: 闲置成本（成本2） | S4: 0 | T4: =SUM(AO4:BC4) -> 0 | U4: =SUM(BA4:BC4) -> 0 | AX4: 0
R5: 差旅费（成本３） | S5: 70000 | T5: =SUM(AO5:BC5) -> 0 | U5: =SUM(BA5:BC5) -> 0 | V5: =SUM(AO5:AZ5) -> 0 | W5: =SUM(AP5:AZ5) -> 0 | X5: =SUM(AQ5:AZ5) -> 0 | Y5: =SUM(AR5:AZ5) -> 0 | Z5: =SUM(AS5:AZ5) -> 0 | AA5: =SUM(AT5:AZ5) -> 0 | AB5: =SUM(AU5:AZ5) -> 0 | AC5: =SUM(AV5:AZ5) -> 0 | AD5: =SUM(AW5:AZ5) -> 0 | AE5: =SUM(AX5:AZ5) -> 0 | AF5: =SUM(AY5:AZ5) -> 0 | AG5: =SUM(AZ5:AZ5) -> 0 | AX5: 0 | AY5: 0 | AZ5: 0 | BA5: 0
